Workbook

Sheet Portada
A1: RoomTrip
A2: Sistema de gestión de reservas de alojamiento en hoteles
A5: Datos de la entrega
A6: Curso | B6: 1TEL05 — Servicios y Aplicaciones para IoT
A7: Carrera | B7: Ingeniería de las Telecomunicaciones — PUCP
A8: Semestre | B8: 2026-2
A9: Proyecto | B9: RoomTrip
A10: Entregable | B10: Lista de requerimientos
A11: Fecha | B11: 23/08/2026
A12: Integrantes
A13: Las celdas resaltadas en amarillo son las que debe completar el equipo antes de entregar.
A15: Descripción del sistema
A16: RoomTrip permite a un cliente consultar hoteles, habitaciones y servicios, reservar con tarjeta, comunicarse con el hotel por chat y solicitar un taxi gratuito al aeropuerto al hacer el checkout.
A17: El sistema se compone de dos aplicaciones con persistencias separadas: una app móvil Android nativa en Java, usada por los cuatro roles, y una app web de gestión de taxistas que expone una API REST.
A18: La app móvil no accede en ningún caso a la base de datos del sistema de taxistas: toda esa información se obtiene a través de la API REST.
A20: Contenido del libro
A21: Hoja | B21: Contenido
A22: Resumen | B22: Distribución de los requerimientos por rol, por módulo funcional y por tipo.
A23: Requerimientos | B23: Catálogo completo con su criterio de aceptación y prioridad.
A24: Por rol | B24: Los mismos requerimientos agrupados por actor del sistema.
A26: Convenciones de identificación
A27: • RF-SA-nn · requerimiento funcional del Superadmin.
A28: • RF-AH-nn · requerimiento funcional del Administrador de hotel.
A29: • RF-TX-nn · requerimiento funcional del Taxista.
A30: • RF-CL-nn · requerimiento funcional del Cliente.
A31: • RF-GN-nn · requerimiento funcional transversal a todos los roles.
A32: • RNF-nn · requerimiento no funcional del sistema.

Sheet Resumen
A1: RoomTrip · Resumen del alcance
A2: 1TEL05 Servicios y Aplicaciones para IoT · PUCP · Semestre 2026-2
A3: Distribución de los requerimientos por rol, por módulo funcional y por tipo.
A5: Alcance del sistema
A6: Total de requerimientos | B6: Funcionales | C6: No funcionales | D6: Prioridad alta | E6: Prioridad media | F6: Módulos funcionales
A7: =COUNTA(Requerimientos!$A$6:$A$52) | B7: =COUNTIF(Requerimientos!$D$6:$D$52,"Funcional") | C7: =COUNTIF(Requerimientos!$D$6:$D$52,"No funcional") | D7: =COUNTIF(Requerimientos!$G$6:$G$52,"Alta") | E7: =COUNTIF(Requerimientos!$G$6:$G$52,"Media") | F7: 10
A9: Requerimientos por rol
A10: Rol | B10: Total | C10: Funcionales | D10: No funcionales | E10: Alta | F10: Media
A11: Superadmin | B11: =COUNTIF(Requerimientos!$C$6:$C$52,$A11) | C11: =COUNTIFS(Requerimientos!$C$6:$C$52,$A11,Requerimientos!$D$6:$D$52,"Funcional") | D11: =COUNTIFS(Requerimientos!$C$6:$C$52,$A11,Requerimientos!$D$6:$D$52,"No funcional") | E11: =COUNTIFS(Requerimientos!$C$6:$C$52,$A11,Requerimientos!$G$6:$G$52,"Alta") | F11: =COUNTIFS(Requerimientos!$C$6:$C$52,$A11,Requerimientos!$G$6:$G$52,"Media")
A12: Administrador de hotel | B12: =COUNTIF(Requerimientos!$C$6:$C$52,$A12) | C12: =COUNTIFS(Requerimientos!$C$6:$C$52,$A12,Requerimientos!$D$6:$D$52,"Funcional") | D12: =COUNTIFS(Requerimientos!$C$6:$C$52,$A12,Requerimientos!$D$6:$D$52,"No funcional") | E12: =COUNTIFS(Requerimientos!$C$6:$C$52,$A12,Requerimientos!$G$6:$G$52,"Alta") | F12: =COUNTIFS(Requerimientos!$C$6:$C$52,$A12,Requerimientos!$G$6:$G$52,"Media")
A13: Taxista | B13: =COUNTIF(Requerimientos!$C$6:$C$52,$A13) | C13: =COUNTIFS(Requerimientos!$C$6:$C$52,$A13,Requerimientos!$D$6:$D$52,"Funcional") | D13: =COUNTIFS(Requerimientos!$C$6:$C$52,$A13,Requerimientos!$D$6:$D$52,"No funcional") | E13: =COUNTIFS(Requerimientos!$C$6:$C$52,$A13,Requerimientos!$G$6:$G$52,"Alta") | F13: =COUNTIFS(Requerimientos!$C$6:$C$52,$A13,Requerimientos!$G$6:$G$52,"Media")
A14: Cliente | B14: =COUNTIF(Requerimientos!$C$6:$C$52,$A14) | C14: =COUNTIFS(Requerimientos!$C$6:$C$52,$A14,Requerimientos!$D$6:$D$52,"Funcional") | D14: =COUNTIFS(Requerimientos!$C$6:$C$52,$A14,Requerimientos!$D$6:$D$52,"No funcional") | E14: =COUNTIFS(Requerimientos!$C$6:$C$52,$A14,Requerimientos!$G$6:$G$52,"Alta") | F14: =COUNTIFS(Requerimientos!$C$6:$C$52,$A14,Requerimientos!$G$6:$G$52,"Media")
A15: Transversal | B15: =COUNTIF(Requerimientos!$C$6:$C$52,$A15) | C15: =COUNTIFS(Requerimientos!$C$6:$C$52,$A15,Requerimientos!$D$6:$D$52,"Funcional") | D15: =COUNTIFS(Requerimientos!$C$6:$C$52,$A15,Requerimientos!$D$6:$D$52,"No funcional") | E15: =COUNTIFS(Requerimientos!$C$6:$C$52,$A15,Requerimientos!$G$6:$G$52,"Alta") | F15: =COUNTIFS(Requerimientos!$C$6:$C$52,$A15,Requerimientos!$G$6:$G$52,"Media")
A16: Total | B16: =SUM(B11:B15) | C16: =SUM(C11:C15) | D16: =SUM(D11:D15) | E16: =SUM(E11:E15) | F16: =SUM(F11:F15)
A18: Requerimientos por módulo funcional
A19: Módulo | B19: Total | C19: Funcionales | D19: No funcionales | E19: Alta | F19: Media
A20: M1 Autenticación | B20: =COUNTIF(Requerimientos!$B$6:$B$52,$A20) | C20: =COUNTIFS(Requerimientos!$B$6:$B$52,$A20,Requerimientos!$D$6:$D$52,"Funcional") | D20: =COUNTIFS(Requerimientos!$B$6:$B$52,$A20,Requerimientos!$D$6:$D$52,"No funcional") | E20: =COUNTIFS(Requerimientos!$B$6:$B$52,$A20,Requerimientos!$G$6:$G$52,"Alta") | F20: =COUNTIFS(Requerimientos!$B$6:$B$52,$A20,Requerimientos!$G$6:$G$52,"Media")
A21: M2 Gestión de usuarios | B21: =COUNTIF(Requerimientos!$B$6:$B$52,$A21) | C21: =COUNTIFS(Requerimientos!$B$6:$B$52,$A21,Requerimientos!$D$6:$D$52,"Funcional") | D21: =COUNTIFS(Requerimientos!$B$6:$B$52,$A21,Requerimientos!$D$6:$D$52,"No funcional") | E21: =COUNTIFS(Requerimientos!$B$6:$B$52,$A21,Requerimientos!$G$6:$G$52,"Alta") | F21: =COUNTIFS(Requerimientos!$B$6:$B$52,$A21,Requerimientos!$G$6:$G$52,"Media")
A22: M3 Catálogo | B22: =COUNTIF(Requerimientos!$B$6:$B$52,$A22) | C22: =COUNTIFS(Requerimientos!$B$6:$B$52,$A22,Requerimientos!$D$6:$D$52,"Funcional") | D22: =COUNTIFS(Requerimientos!$B$6:$B$52,$A22,Requerimientos!$D$6:$D$52,"No funcional") | E22: =COUNTIFS(Requerimientos!$B$6:$B$52,$A22,Requerimientos!$G$6:$G$52,"Alta") | F22: =COUNTIFS(Requerimientos!$B$6:$B$52,$A22,Requerimientos!$G$6:$G$52,"Media")
A23: M4 Reservas | B23: =COUNTIF(Requerimientos!$B$6:$B$52,$A23) | C23: =COUNTIFS(Requerimientos!$B$6:$B$52,$A23,Requerimientos!$D$6:$D$52,"Funcional") | D23: =COUNTIFS(Requerimientos!$B$6:$B$52,$A23,Requerimientos!$D$6:$D$52,"No funcional") | E23: =COUNTIFS(Requerimientos!$B$6:$B$52,$A23,Requerimientos!$G$6:$G$52,"Alta") | F23: =COUNTIFS(Requerimientos!$B$6:$B$52,$A23,Requerimientos!$G$6:$G$52,"Media")
A24: M5 Pagos y cobros | B24: =COUNTIF(Requerimientos!$B$6:$B$52,$A24) | C24: =COUNTIFS(Requerimientos!$B$6:$B$52,$A24,Requerimientos!$D$6:$D$52,"Funcional") | D24: =COUNTIFS(Requerimientos!$B$6:$B$52,$A24,Requerimientos!$D$6:$D$52,"No funcional") | E24: =COUNTIFS(Requerimientos!$B$6:$B$52,$A24,Requerimientos!$G$6:$G$52,"Alta") | F24: =COUNTIFS(Requerimientos!$B$6:$B$52,$A24,Requerimientos!$G$6:$G$52,"Media")
A25: M6 Checkout y valoraciones | B25: =COUNTIF(Requerimientos!$B$6:$B$52,$A25) | C25: =COUNTIFS(Requerimientos!$B$6:$B$52,$A25,Requerimientos!$D$6:$D$52,"Funcional") | D25: =COUNTIFS(Requerimientos!$B$6:$B$52,$A25,Requerimientos!$D$6:$D$52,"No funcional") | E25: =COUNTIFS(Requerimientos!$B$6:$B$52,$A25,Requerimientos!$G$6:$G$52,"Alta") | F25: =COUNTIFS(Requerimientos!$B$6:$B$52,$A25,Requerimientos!$G$6:$G$52,"Media")
A26: M7 Chat | B26: =COUNTIF(Requerimientos!$B$6:$B$52,$A26) | C26: =COUNTIFS(Requerimientos!$B$6:$B$52,$A26,Requerimientos!$D$6:$D$52,"Funcional") | D26: =COUNTIFS(Requerimientos!$B$6:$B$52,$A26,Requerimientos!$D$6:$D$52,"No funcional") | E26: =COUNTIFS(Requerimientos!$B$6:$B$52,$A26,Requerimientos!$G$6:$G$52,"Alta") | F26: =COUNTIFS(Requerimientos!$B$6:$B$52,$A26,Requerimientos!$G$6:$G$52,"Media")
A27: M8 Taxi | B27: =COUNTIF(Requerimientos!$B$6:$B$52,$A27) | C27: =COUNTIFS(Requerimientos!$B$6:$B$52,$A27,Requerimientos!$D$6:$D$52,"Funcional") | D27: =COUNTIFS(Requerimientos!$B$6:$B$52,$A27,Requerimientos!$D$6:$D$52,"No funcional") | E27: =COUNTIFS(Requerimientos!$B$6:$B$52,$A27,Requerimientos!$G$6:$G$52,"Alta") | F27: =COUNTIFS(Requerimientos!$B$6:$B$52,$A27,Requerimientos!$G$6:$G$52,"Media")
A28: M9 Reportes y logs | B28: =COUNTIF(Requerimientos!$B$6:$B$52,$A28) | C28: =COUNTIFS(Requerimientos!$B$6:$B$52,$A28,Requerimientos!$D$6:$D$52,"Funcional") | D28: =COUNTIFS(Requerimientos!$B$6:$B$52,$A28,Requerimientos!$D$6:$D$52,"No funcional") | E28: =COUNTIFS(Requerimientos!$B$6:$B$52,$A28,Requerimientos!$G$6:$G$52,"Alta") | F28: =COUNTIFS(Requerimientos!$B$6:$B$52,$A28,Requerimientos!$G$6:$G$52,"Media")
A29: M10 Calidad | B29: =COUNTIF(Requerimientos!$B$6:$B$52,$A29) | C29: =COUNTIFS(Requerimientos!$B$6:$B$52,$A29,Requerimientos!$D$6:$D$52,"Funcional") | D29: =COUNTIFS(Requerimientos!$B$6:$B$52,$A29,Requerimientos!$D$6:$D$52,"No funcional") | E29: =COUNTIFS(Requerimientos!$B$6:$B$52,$A29,Requerimientos!$G$6:$G$52,"Alta") | F29: =COUNTIFS(Requerimientos!$B$6:$B$52,$A29,Requerimientos!$G$6:$G$52,"Media")
A30: Total | B30: =SUM(B20:B29) | C30: =SUM(C20:C29) | D30: =SUM(D20:D29) | E30: =SUM(E20:E29) | F30: =SUM(F20:F29)

Sheet Requerimientos
A1: RoomTrip · Lista de requerimientos
A2: 1TEL05 Servicios y Aplicaciones para IoT · PUCP · Semestre 2026-2
A3: Sistema de gestión de reservas de alojamiento en hoteles vía aplicación móvil.
A5: ID | B5: Módulo | C5: Rol | D5: Tipo | E5: Requerimiento | F5: Criterio de aceptación | G5: Prioridad
A6: RF-SA-01 | B6: M2 Gestión de usuarios | C6: Superadmin | D6: Funcional | E6: Activar y desactivar administradores de hotel taxistas y clientes | F6: Al desactivar un usuario este no puede iniciar sesión y al reactivarlo recupera el acceso | G6: Alta
A7: RF-SA-02 | B7: M2 Gestión de usuarios | C7: Superadmin | D7: Funcional | E7: Registrar hoteles y asignar un administrador a cada uno | F7: Un hotel registrado queda asociado a exactamente un administrador que ve solo ese hotel | G7: Alta
A8: RF-SA-04 | B8: M9 Reportes y logs | C8: Superadmin | D8: Funcional | E8: Generar el reporte de reservas por hotel | F8: El reporte agrupa las reservas por hotel | G8: Media
A9: RF-SA-05 | B9: M9 Reportes y logs | C9: Superadmin | D9: Funcional | E9: Consultar el visor de logs de eventos del sistema | F9: El Superadmin ve los eventos registrados con fecha actor y tipo de evento | G9: Media
A10: RF-SA-03 | B10: M2 Gestión de usuarios | C10: Superadmin | D10: Funcional | E10: Aprobar o habilitar taxistas desde la app web | F10: El taxista pasa de pendiente a habilitado y recién entonces aparece como disponible | G10: Alta
A11: RF-AH-02 | B11: M3 Catálogo | C11: Administrador de hotel | D11: Funcional | E11: Subir fotos del hotel con un mínimo de 4 | F11: El formulario no permite guardar con menos de 4 fotos | G11: Alta
A12: RF-AH-03 | B12: M3 Catálogo | C12: Administrador de hotel | D12: Funcional | E12: Registrar habitaciones con tipo capacidad de adultos y niños y tamaño en m2 | F12: La habitación guardada muestra los 4 datos y queda listada en el hotel | G12: Alta
A13: RF-AH-04 | B13: M3 Catálogo | C13: Administrador de hotel | D13: Funcional | E13: Registrar servicios con nombre descripción precio imágenes y si tienen costo | F13: Un servicio marcado sin costo no suma al total de la reserva | G13: Alta
A14: RF-AH-06 | B14: M5 Pagos y cobros | C14: Administrador de hotel | D14: Funcional | E14: Recibir la alerta de checkout y procesar el cobro de la tarjeta registrada | F14: Al hacer checkout el cliente el hotel recibe la alerta y puede ejecutar el cobro | G14: Alta
A15: RF-AH-09 | B15: M7 Chat | C15: Administrador de hotel | D15: Funcional | E15: Responder los chats de clientes con reserva activa | F15: El hotel ve solo los chats de reservas activas y puede responder | G15: Alta
A16: RF-AH-10 | B16: M8 Taxi | C16: Administrador de hotel | D16: Funcional | E16: Establecer el monto mínimo de reserva que da derecho al taxi gratuito al aeropuerto | F16: El hotel guarda un monto mínimo y solo las reservas que lo alcanzan habilitan la opción de taxi al cliente | G16: Alta
... A52: RNF-09 | B52: M10 Calidad | C52: Transversal | D52: No funcional | E52: La app móvil no accede directamente a la base de datos del sistema de taxistas | F52: Toda información de taxistas llega por la API REST vía TaxiRepository | G52: Alta

Sheet Por rol
A1: RoomTrip · Requerimientos agrupados por rol
A2: 1TEL05 Servicios y Aplicaciones para IoT · PUCP · Semestre 2026-2
A3: Los mismos requerimientos de la hoja anterior, organizados por actor del sistema.
A5: ID | B5: Requerimiento | C5: Criterio de aceptación | D5: Módulo | E5: Tipo | F5: Prioridad
A6: Superadmin · 5 requerimientos
A7: RF-SA-01 | B7: Activar y desactivar administradores de hotel taxistas y clientes | C7: Al desactivar un usuario este no puede iniciar sesión y al reactivarlo recupera el acceso | D7: M2 Gestión de usuarios | E7: Funcional | F7: Alta
A8: RF-SA-02 | B8: Registrar hoteles y asignar un administrador a cada uno | C8: Un hotel registrado queda asociado a exactamente un administrador que ve solo ese hotel | D8: M2 Gestión de usuarios | E8: Funcional | F8: Alta
A9: RF-SA-04 | B9: Generar el reporte de reservas por hotel | C9: El reporte agrupa las reservas por hotel | D9: M9 Reportes y logs | E9: Funcional | F9: Media
A10: RF-SA-05 | B10: Consultar el visor de logs de eventos del sistema | C10: El Superadmin ve los eventos registrados con fecha actor y tipo de evento | D10: M9 Reportes y logs | E10: Funcional | F10: Media
A11: RF-SA-03 | B11: Aprobar o habilitar taxistas desde la app web | C11: El taxista pasa de pendiente a habilitado y recién entonces aparece como disponible | D11: M2 Gestión de usuarios | E11: Funcional | F11: Alta
A13: Administrador de hotel · 10 requerimientos
A14: RF-AH-02 | B14: Subir fotos del hotel con un mínimo de 4 | C14: El formulario no permite guardar con menos de 4 fotos | D14: M3 Catálogo | E14: Funcional | F14: Alta
A15: RF-AH-03 | B15: Registrar habitaciones con tipo capacidad de adultos y niños y tamaño en m2 | C15: La habitación guardada muestra los 4 datos y queda listada en el hotel | D15: M3 Catálogo | E15: Funcional | F15: Alta
A16: RF-AH-04 | B16: Registrar servicios con nombre descripción precio imágenes y si tienen costo | C16: Un servicio marcado sin costo no suma al total de la reserva | D16: M3 Catálogo | E16: Funcional | F16: Alta
A17: RF-AH-06 | B17: Recibir la alerta de checkout y procesar el cobro de la tarjeta registrada | C17: Al hacer checkout el cliente el hotel recibe la alerta y puede ejecutar el cobro | D17: M5 Pagos y cobros | E17: Funcional | F17: Alta
A18: RF-AH-09 | B18: Responder los chats de clientes con reserva activa | C18: El hotel ve solo los chats de reservas activas y puede responder | D18: M7 Chat | E18: Funcional | F18: Alta
A19: RF-AH-10 | B19: Establecer el monto mínimo de reserva que da derecho al taxi gratuito al aeropuerto | C19: El hotel guarda un monto mínimo y solo las reservas que lo alcanzan habilitan la opción de taxi al cliente | D19: M8 Taxi | E19: Funcional | F19: Alta
A20: RF-AH-07 | B20: Añadir cobros adicionales por daños con monto motivo y observación | C20: El cobro adicional exige los 3 campos y se suma al total de la reserva | D20: M5 Pagos y cobros | E20: Funcional | F20: Media
A21: RF-AH-08 | B21: Reporte de ingresos por servicios adicionales ordenado de menor a mayor | C21: El reporte lista los servicios ordenados ascendentemente por monto total generado | D21: M9 Reportes y logs | E21: Funcional | F21: Media
A22: RF-AH-01 | B22: Registrar la ubicación del hotel y los lugares históricos cercanos | C22: La ubicación se selecciona en un mapa y se listan los lugares históricos cercanos asociados | D22: M3 Catálogo | E22: Funcional | F22: Alta
A23: RF-AH-05 | B23: Ver el estado del taxista asignado en camino a recoger y llegó al destino | C23: El hotel ve el estado actualizado del servicio de taxi de sus huéspedes | D23: M8 Taxi | E23: Funcional | F23: Media
A25: Taxista · 7 requerimientos
A26: RF-TX-02 | B26: Acceder a la app móvil una vez habilitado | C26: Un taxista no habilitado no puede iniciar sesión en la app móvil y uno habilitado sí | D26: M1 Autenticación | E26: Funcional | F26: Alta
A27: RF-TX-03 | B27: Ver hoteles y pedidos disponibles | C27: El taxista habilitado ve la lista de pedidos en estado SOLICITADO | D27: M8 Taxi | E27: Funcional | F27: Alta
A28: RF-TX-04 | B28: Aceptar un pedido que deja de estar disponible para los demás | C28: Al aceptar el servicio pasa a ASIGNADO y desaparece de la lista de los otros taxistas | D28: M8 Taxi | E28: Funcional | F28: Alta
A29: RF-TX-06 | B29: Actualizar los estados del servicio | C29: El taxista avanza el servicio por SOLICITADO ASIGNADO EN_CAMINO EN_TRASLADO y FINALIZADO | D29: M8 Taxi | E29: Funcional | F29: Alta
A30: RF-TX-05 | B30: Registrar automáticamente su ubicación durante el servicio activo | C30: Con un servicio activo la ubicación se actualiza periódicamente sin intervención del taxista | D30: M8 Taxi | E30: Funcional | F30: Alta
A31: RF-TX-07 | B31: Registrar FINALIZADO únicamente escaneando el QR del cliente | C31: El estado FINALIZADO no se puede fijar manualmente y solo se alcanza por escaneo del QR | D31: M8 Taxi | E31: Funcional | F31: Alta
A32: RF-TX-01 | B32: Autoregistrarse en la app web con todos sus datos y fotos | C32: El formulario web exige nombres apellidos tipo y número de documento fecha de nacimiento correo teléfono domicilio foto placa y foto del vehículo | D32: M1 Autenticación | E32: Funcional | F32: Alta
A34: Cliente · 12 requerimientos
A35: RF-CL-01 | B35: Autoregistrarse y quedar habilitado automáticamente | C35: Al completar el formulario con nombres apellidos tipo y número de documento fecha de nacimiento correo teléfono domicilio y foto la cuenta queda activa sin aprobación | D35: M1 Autenticación | E35: Funcional | F35: Alta
A36: RF-CL-02 | B36: Consultar hoteles habitaciones servicios disponibilidad y valoraciones | C36: El listado muestra hoteles con sus fotos habitaciones servicios y promedio de valoraciones | D36: M3 Catálogo | E36: Funcional | F36: Alta
A37: RF-CL-03 | B37: Reservar con tarjeta de crédito o débito simulada | C37: Tras confirmar el pago simulado la reserva queda creada y visible en el historial | D37: M4 Reservas | E37: Funcional | F37: Alta
A38: RF-CL-04 | B38: Hacer checkout y registrar valoración y observaciones obligatorias | C38: No se puede completar el checkout sin valoración y observaciones | D38: M6 Checkout y valoraciones | E38: Funcional | F38: Alta
A39: RF-CL-05 | B39: Recibir notificación cuando se le hace el cobro | C39: El cliente recibe una notificación push con el monto cobrado | D39: M5 Pagos y cobros | E39: Funcional | F39: Alta
A40: RF-CL-07 | B40: Chat privado con el hotel entre la confirmación de la reserva y el fin del checkout | C40: El chat no está disponible antes de confirmar la reserva ni después del checkout | D40: M7 Chat | E40: Funcional | F40: Alta
A41: RF-CL-06 | B41: Ver el historial de sus reservas | C41: El historial lista las reservas del cliente autenticado con fechas hotel habitación estado y monto | D41: M4 Reservas | E41: Funcional | F41: Media
A42: RF-CL-12 | B42: Consultar los lugares históricos cercanos al hotel | C42: El cliente ve la lista de lugares históricos cercanos registrados por el administrador del hotel | D42: M3 Catálogo | E42: Funcional | F42: Media
A43: RF-CL-08 | B43: Solicitar el taxi gratuito al aeropuerto si la reserva alcanza el monto mínimo | C43: La opción aparece solo si el monto de la reserva alcanza el mínimo del hotel es opcional y el cliente indica el aeropuerto destino | D43: M8 Taxi | E43: Funcional | F43: Alta
A44: RF-CL-09 | B44: Ver datos vehículo valoración y ubicación del taxista en un mapa | C44: El cliente ve nombre vehículo placa valoración y la posición del taxista actualizándose en el mapa | D44: M8 Taxi | E44: Funcional | F44: Alta
...
