Workbook

Sheet Guía
A1: RoomTrip · Cómo usar este libro
A2: Matriz de requerimientos del proyecto · versión inicial 23/08/2026
A5: Hojas del libro
A6: Hoja | B6: Para qué sirve | C6: ¿Se edita?
A7: Resumen | B7: Indicadores del proyecto: avance por rol, por entregable y por módulo. Todo calculado con fórmulas. | C7: No. Se actualiza solo.
A8: Requerimientos | B8: Tabla maestra con los 45 requerimientos y todos sus atributos. Tiene filtros y listas desplegables. | C8: Sí. Es la única hoja editable.
A9: Por rol | B9: Los mismos requerimientos agrupados por rol, para repartir el trabajo entre el equipo. | C9: No. Refleja la maestra.
A10: Por entregable | B10: Los mismos requerimientos agrupados por laboratorio, con la fecha de cada entrega. | C10: No. Refleja la maestra.
A11: Guía | B11: Esta hoja: significado de cada columna y convenciones. | C11: No.
A13: Significado de las columnas
A14: Columna | B14: Qué contiene | C14: Valores admitidos
A15: ID | B15: Identificador trazable con el enunciado del curso. | C15: RF-<ROL>-<NN> · RNF-<NN>
A16: Módulo | B16: Agrupación funcional del sistema. | C16: M1 a M10
A17: Rol | B17: Quién ejecuta el requerimiento. | C17: Los 4 roles + Transversal
A18: Tipo | B18: Naturaleza del requerimiento. | C18: Funcional · No funcional
A19: Requerimiento | B19: Enunciado en una línea. | C19: Texto libre
A20: Criterio de aceptación | B20: Cómo se comprueba que está cumplido. Es lo que lo hace evaluable. | C20: Texto libre
A21: Prioridad | B21: Urgencia relativa. | C21: Alta · Media · Baja
A22: Entregable | B22: Laboratorio en el que se implementa. | C22: Lab 3 a Lab 7 · Final
A23: Foco técnico | B23: Tecnología principal que exige ese entregable. | C23: Texto
A24: Depende de | B24: ID del requerimiento que debe existir antes. Define el orden de trabajo. | C24: Un ID o vacío
A25: Estado | B25: Avance real. | C25: Pendiente · En progreso · Hecho · Bloqueado
... A28: Observaciones | B28: Notas, riesgos y detalles pendientes. | C28: Texto libre
A30: Convenciones de trabajo
A31: • Editar únicamente la hoja «Requerimientos». Las demás se actualizan solas.
A32: • Al añadir un requerimiento nuevo, insertar la fila dentro del rango existente para que las fórmulas del Resumen lo tomen.
A33: • Los IDs no se reutilizan: si un requerimiento se elimina, su ID queda retirado.
A34: • El campo «Depende de» marca el orden real de implementación; revisarlo antes de repartir tareas.
A35: • Los cambios de este libro se versionan en el repositorio junto con docs/requerimientos.md.

Sheet Resumen
A1: RoomTrip · Resumen de requerimientos
A2: Todos los valores se calculan con fórmulas sobre la hoja Requerimientos
A3: Actualiza automáticamente al cambiar el estado de un requerimiento.
A5: Indicadores generales
A6: Total de requerimientos | B6: Funcionales | C6: No funcionales | D6: Prioridad alta | E6: Hechos | F6: En progreso | G6: Pendientes | H6: % de avance | I6: Mockups faltantes
A7: =COUNTA(Requerimientos!$A$6:$A$50) -> 45 | B7: =COUNTIF(Requerimientos!$D$6:$D$50,"Funcional") -> 36 | C7: =COUNTIF(Requerimientos!$D$6:$D$50,"No funcional") -> 9 | D7: =COUNTIF(Requerimientos!$G$6:$G$50,"Alta") -> 37 | E7: =COUNTIF(Requerimientos!$K$6:$K$50,"Hecho") -> 0 | F7: =COUNTIF(Requerimientos!$K$6:$K$50,"En progreso") -> 0 | G7: =COUNTIF(Requerimientos!$K$6:$K$50,"Pendiente") -> 45 | H7: =IFERROR(COUNTIF(Requerimientos!$K$6:$K$50,"Hecho")/COUNTA(Requerimientos!$A$6:$A$50),0) -> 0 | I7: =COUNTIF(Requerimientos!$L$6:$L$50,"No") -> 17
A9: Requerimientos por rol
A10: Rol | B10: Total | C10: Alta | D10: Media | E10: Pendiente | F10: En progreso | G10: Hecho | H10: % avance | I10: Sin mockup
A11: Superadmin | B11: =COUNTIF(Requerimientos!$C$6:$C$50,$A11) -> 5 | C11: =COUNTIFS(Requerimientos!$C$6:$C$50,$A11,Requerimientos!$G$6:$G$50,"Alta") -> 3 | D11: =COUNTIFS(Requerimientos!$C$6:$C$50,$A11,Requerimientos!$G$6:$G$50,"Media") -> 2 | E11: =COUNTIFS(Requerimientos!$C$6:$C$50,$A11,Requerimientos!$K$6:$K$50,"Pendiente") -> 5 | F11: =COUNTIFS(Requerimientos!$C$6:$C$50,$A11,Requerimientos!$K$6:$K$50,"En progreso") -> 0 | G11: =COUNTIFS(Requerimientos!$C$6:$C$50,$A11,Requerimientos!$K$6:$K$50,"Hecho") -> 0 | H11: =IFERROR($G11/$B11,0) -> 0 | I11: =COUNTIFS(Requerimientos!$C$6:$C$50,$A11,Requerimientos!$L$6:$L$50,"No") -> 5
A12: Administrador de hotel | B12: =COUNTIF(Requerimientos!$C$6:$C$50,$A12) -> 9 | C12: =COUNTIFS(Requerimientos!$C$6:$C$50,$A12,Requerimientos!$G$6:$G$50,"Alta") -> 6 | D12: =COUNTIFS(Requerimientos!$C$6:$C$50,$A12,Requerimientos!$G$6:$G$50,"Media") -> 3 | E12: =COUNTIFS(Requerimientos!$C$6:$C$50,$A12,Requerimientos!$K$6:$K$50,"Pendiente") -> 9 | F12: =COUNTIFS(Requerimientos!$C$6:$C$50,$A12,Requerimientos!$K$6:$K$50,"En progreso") -> 0 | G12: =COUNTIFS(Requerimientos!$C$6:$C$50,$A12,Requerimientos!$K$6:$K$50,"Hecho") -> 0 | H12: =IFERROR($G12/$B12,0) -> 0 | I12: =COUNTIFS(Requerimientos!$C$6:$C$50,$A12,Requerimientos!$L$6:$L$50,"No") -> 1
A13: Taxista | B13: =COUNTIF(Requerimientos!$C$6:$C$50,$A13) -> 7 | C13: =COUNTIFS(Requerimientos!$C$6:$C$50,$A13,Requerimientos!$G$6:$G$50,"Alta") -> 7 | D13: =COUNTIFS(Requerimientos!$C$6:$C$50,$A13,Requerimientos!$G$6:$G$50,"Media") -> 0 | E13: =COUNTIFS(Requerimientos!$C$6:$C$50,$A13,Requerimientos!$K$6:$K$50,"Pendiente") -> 7 | F13: =COUNTIFS(Requerimientos!$C$6:$C$50,$A13,Requerimientos!$K$6:$K$50,"En progreso") -> 0 | G13: =COUNTIFS(Requerimientos!$C$6:$C$50,$A13,Requerimientos!$K$6:$K$50,"Hecho") -> 0 | H13: =IFERROR($G13/$B13,0) -> 0 | I13: =COUNTIFS(Requerimientos!$C$6:$C$50,$A13,Requerimientos!$L$6:$L$50,"No") -> 7
A14: Cliente | B14: =COUNTIF(Requerimientos!$C$6:$C$50,$A14) -> 11 | C14: =COUNTIFS(Requerimientos!$C$6:$C$50,$A14,Requerimientos!$G$6:$G$50,"Alta") -> 9 | D14: =COUNTIFS(Requerimientos!$C$6:$C$50,$A14,Requerimientos!$G$6:$G$50,"Media") -> 2 | E14: =COUNTIFS(Requerimientos!$C$6:$C$50,$A14,Requerimientos!$K$6:$K$50,"Pendiente") -> 11 | F14: =COUNTIFS(Requerimientos!$C$6:$C$50,$A14,Requerimientos!$K$6:$K$50,"En progreso") -> 0 | G14: =COUNTIFS(Requerimientos!$C$6:$C$50,$A14,Requerimientos!$K$6:$K$50,"Hecho") -> 0 | H14: =IFERROR($G14/$B14,0) -> 0 | I14: =COUNTIFS(Requerimientos!$C$6:$C$50,$A14,Requerimientos!$L$6:$L$50,"No") -> 4
A15: Transversal | B15: =COUNTIF(Requerimientos!$C$6:$C$50,$A15) -> 13 | C15: =COUNTIFS(Requerimientos!$C$6:$C$50,$A15,Requerimientos!$G$6:$G$50,"Alta") -> 12 | D15: =COUNTIFS(Requerimientos!$C$6:$C$50,$A15,Requerimientos!$G$6:$G$50,"Media") -> 1 | E15: =COUNTIFS(Requerimientos!$C$6:$C$50,$A15,Requerimientos!$K$6:$K$50,"Pendiente") -> 13 | F15: =COUNTIFS(Requerimientos!$C$6:$C$50,$A15,Requerimientos!$K$6:$K$50,"En progreso") -> 0 | G15: =COUNTIFS(Requerimientos!$C$6:$C$50,$A15,Requerimientos!$K$6:$K$50,"Hecho") -> 0 | H15: =IFERROR($G15/$B15,0) -> 0 | I15: =COUNTIFS(Requerimientos!$C$6:$C$50,$A15,Requerimientos!$L$6:$L$50,"No") -> 0
A16: Total | B16: =SUM(B11:B15) -> 45 | C16: =SUM(C11:C15) -> 37 | D16: =SUM(D11:D15) -> 8 | E16: =SUM(E11:E15) -> 45 | F16: =SUM(F11:F15) -> 0 | G16: =SUM(G11:G15) -> 0 | H16: =IFERROR($G16/$B16,0) -> 0 | I16: =SUM(I11:I15) -> 17
A18: Requerimientos por entregable
A19: Entregable | B19: Fecha | C19: Días restantes | D19: Total | E19: Alta | F19: Pendiente | G19: Hecho | H19: % avance | I19: Sin mockup
A20: Lab 3 | B20: 46280 | C20: =$B20-TODAY() -> 23 | D20: =COUNTIF(Requerimientos!$H$6:$H$50,$A20) -> 1 | E20: =COUNTIFS(Requerimientos!$H$6:$H$50,$A20,Requerimientos!$G$6:$G$50,"Alta") -> 1 | F20: =COUNTIFS(Requerimientos!$H$6:$H$50,$A20,Requerimientos!$K$6:$K$50,"Pendiente") -> 1 | G20: =COUNTIFS(Requerimientos!$H$6:$H$50,$A20,Requerimientos!$K$6:$K$50,"Hecho") -> 0 | H20: =IFERROR($G20/$D20,0) -> 0 | I20: =COUNTIFS(Requerimientos!$H$6:$H$50,$A20,Requerimientos!$L$6:$L$50,"No") -> 0
A21: Lab 4 | B21: 46294 | C21: =$B21-TODAY() -> 37 | D21: =COUNTIF(Requerimientos!$H$6:$H$50,$A21) -> 4 | E21: =COUNTIFS(Requerimientos!$H$6:$H$50,$A21,Requerimientos!$G$6:$G$50,"Alta") -> 3 | F21: =COUNTIFS(Requerimientos!$H$6:$H$50,$A21,Requerimientos!$K$6:$K$50,"Pendiente") -> 4 | G21: =COUNTIFS(Requerimientos!$H$6:$H$50,$A21,Requerimientos!$K$6:$K$50,"Hecho") -> 0 | H21: =IFERROR($G21/$D21,0) -> 0 | I21: =COUNTIFS(Requerimientos!$H$6:$H$50,$A21,Requerimientos!$L$6:$L$50,"No") -> 0
A22: Lab 5 | B22: 46315 | C22: =$B22-TODAY() -> 58 | D22: =COUNTIF(Requerimientos!$H$6:$H$50,$A22) -> 3 | E22: =COUNTIFS(Requerimientos!$H$6:$H$50,$A22,Requerimientos!$G$6:$G$50,"Alta") -> 3 | F22: =COUNTIFS(Requerimientos!$H$6:$H$50,$A22,Requerimientos!$K$6:$K$50,"Pendiente") -> 3 | G22: =COUNTIFS(Requerimientos!$H$6:$H$50,$A22,Requerimientos!$K$6:$K$50,"Hecho") -> 0 | H22: =IFERROR($G22/$D22,0) -> 0 | I22: =COUNTIFS(Requerimientos!$H$6:$H$50,$A22,Requerimientos!$L$6:$L$50,"No") -> 0
A23: Lab 6 | B23: 46329 | C23: =$B23-TODAY() -> 72 | D23: =COUNTIF(Requerimientos!$H$6:$H$50,$A23) -> 19 | E23: =COUNTIFS(Requerimientos!$H$6:$H$50,$A23,Requerimientos!$G$6:$G$50,"Alta") -> 17 | F23: =COUNTIFS(Requerimientos!$H$6:$H$50,$A23,Requerimientos!$K$6:$K$50,"Pendiente") -> 19 | G23: =COUNTIFS(Requerimientos!$H$6:$H$50,$A23,Requerimientos!$K$6:$K$50,"Hecho") -> 0 | H23: =IFERROR($G23/$D23,0) -> 0 | I23: =COUNTIFS(Requerimientos!$H$6:$H$50,$A23,Requerimientos!$L$6:$L$50,"No") -> 4
A24: Lab 7 | B24: 46370 | C24: =$B24-TODAY() -> 113 | D24: =COUNTIF(Requerimientos!$H$6:$H$50,$A24) -> 16 | E24: =COUNTIFS(Requerimientos!$H$6:$H$50,$A24,Requerimientos!$G$6:$G$50,"Alta") -> 11 | F24: =COUNTIFS(Requerimientos!$H$6:$H$50,$A24,Requerimientos!$K$6:$K$50,"Pendiente") -> 16 | G24: =COUNTIFS(Requerimientos!$H$6:$H$50,$A24,Requerimientos!$K$6:$K$50,"Hecho") -> 0 | H24: =IFERROR($G24/$D24,0) -> 0 | I24: =COUNTIFS(Requerimientos!$H$6:$H$50,$A24,Requerimientos!$L$6:$L$50,"No") -> 11
A25: Final | B25: Por definir | C25: — | D25: =COUNTIF(Requerimientos!$H$6:$H$50,$A25) -> 2 | E25: =COUNTIFS(Requerimientos!$H$6:$H$50,$A25,Requerimientos!$G$6:$G$50,"Alta") -> 2 | F25: =COUNTIFS(Requerimientos!$H$6:$H$50,$A25,Requerimientos!$K$6:$K$50,"Pendiente") -> 2 | G25: =COUNTIFS(Requerimientos!$H$6:$H$50,$A25,Requerimientos!$K$6:$K$50,"Hecho") -> 0 | H25: =IFERROR($G25/$D25,0) -> 0 | I25: =COUNTIFS(Requerimientos!$H$6:$H$50,$A25,Requerimientos!$L$6:$L$50,"No") -> 2
A27: Requerimientos por módulo funcional
A28: Módulo | B28: Total | C28: Alta | D28: Pendiente | E28: Hecho | F28: % avance
A29: M1 Autenticación | B29: =COUNTIF(Requerimientos!$B$6:$B$50,$A29) -> 4 | C29: =COUNTIFS(Requerimientos!$B$6:$B$50,$A29,Requerimientos!$G$6:$G$50,"Alta") -> 4 | D29: =COUNTIFS(Requerimientos!$B$6:$B$50,$A29,Requerimientos!$K$6:$K$50,"Pendiente") -> 4 | E29: =COUNTIFS(Requerimientos!$B$6:$B$50,$A29,Requerimientos!$K$6:$K$50,"Hecho") -> 0 | F29: =IFERROR($E29/$B29,0) -> 0
A30: M2 Gestión de usuarios | B30: =COUNTIF(Requerimientos!$B$6:$B$50,$A30) -> 3 | C30: =COUNTIFS(Requerimientos!$B$6:$B$50,$A30,Requerimientos!$G$6:$G$50,"Alta") -> 3 | D30: =COUNTIFS(Requerimientos!$B$6:$B$50,$A30,Requerimientos!$K$6:$K$50,"Pendiente") -> 3 | E30: =COUNTIFS(Requerimientos!$B$6:$B$50,$A30,Requerimientos!$K$6:$K$50,"Hecho") -> 0 | F30: =IFERROR($E30/$B30,0) -> 0
A31: M3 Catálogo | B31: =COUNTIF(Requerimientos!$B$6:$B$50,$A31) -> 5 | C31: =COUNTIFS(Requerimientos!$B$6:$B$50,$A31,Requerimientos!$G$6:$G$50,"Alta") -> 5 | D31: =COUNTIFS(Requerimientos!$B$6:$B$50,$A31,Requerimientos!$K$6:$K$50,"Pendiente") -> 5 | E31: =COUNTIFS(Requerimientos!$B$6:$B$50,$A31,Requerimientos!$K$6:$K$50,"Hecho") -> 0 | F31: =IFERROR($E31/$B31,0) -> 0
A32: M4 Reservas | B32: =COUNTIF(Requerimientos!$B$6:$B$50,$A32) -> 4 | C32: =COUNTIFS(Requerimientos!$B$6:$B$50,$A32,Requerimientos!$G$6:$G$50,"Alta") -> 3 | D32: =COUNTIFS(Requerimientos!$B$6:$B$50,$A32,Requerimientos!$K$6:$K$50,"Pendiente") -> 4 | E32: =COUNTIFS(Requerimientos!$B$6:$B$50,$A32,Requerimientos!$K$6:$K$50,"Hecho") -> 0 | F32: =IFERROR($E32/$B32,0) -> 0
A33: M5 Pagos y cobros | B33: =COUNTIF(Requerimientos!$B$6:$B$50,$A33) -> 3 | C33: =COUNTIFS(Requerimientos!$B$6:$B$50,$A33,Requerimientos!$G$6:$G$50,"Alta") -> 2 | D33: =COUNTIFS(Requerimientos!$B$6:$B$50,$A33,Requerimientos!$K$6:$K$50,"Pendiente") -> 3 | E33: =COUNTIFS(Requerimientos!$B$6:$B$50,$A33,Requerimientos!$K$6:$K$50,"Hecho") -> 0 | F33: =IFERROR($E33/$B33,0) -> 0
A34: M6 Checkout y valoraciones | B34: =COUNTIF(Requerimientos!$B$6:$B$50,$A34) -> 1 | C34: =COUNTIFS(Requerimientos!$B$6:$B$50,$A34,Requerimientos!$G$6:$G$50,"Alta") -> 1 | D34: =COUNTIFS(Requerimientos!$B$6:$B$50,$A34,Requerimientos!$K$6:$K$50,"Pendiente") -> 1 | E34: =COUNTIFS(Requerimientos!$B$6:$B$50,$A34,Requerimientos!$K$6:$K$50,"Hecho") -> 0 | F34: =IFERROR($E34/$B34,0) -> 0
A35: M7 Chat | B35: =COUNTIF(Requerimientos!$B$6:$B$50,$A35) -> 3 | C35: =COUNTIFS(Requerimientos!$B$6:$B$50,$A35,Requerimientos!$G$6:$G$50,"Alta") -> 3 | D35: =COUNTIFS(Requerimientos!$B$6:$B$50,$A35,Requerimientos!$K$6:$K$50,"Pendiente") -> 3 | E35: =COUNTIFS(Requerimientos!$B$6:$B$50,$A35,Requerimientos!$K$6:$K$50,"Hecho") -> 0 | F35: =IFERROR($E35/$B35,0) -> 0
A36: M8 Taxi | B36: =COUNTIF(Requerimientos!$B$6:$B$50,$A36) -> 10 | C36: =COUNTIFS(Requerimientos!$B$6:$B$50,$A36,Requerimientos!$G$6:$G$50,"Alta") -> 8 | D36: =COUNTIFS(Requerimientos!$B$6:$B$50,$A36,Requerimientos!$K$6:$K$50,"Pendiente") -> 10 | E36: =COUNTIFS(Requerimientos!$B$6:$B$50,$A36,Requerimientos!$K$6:$K$50,"Hecho") -> 0 | F36: =IFERROR($E36/$B36,0) -> 0
A37: M9 Reportes y logs | B37: =COUNTIF(Requerimientos!$B$6:$B$50,$A37) -> 3 | C37: =COUNTIFS(Requerimientos!$B$6:$B$50,$A37,Requerimientos!$G$6:$G$50,"Alta") -> 0 | D37: =COUNTIFS(Requerimientos!$B$6:$B$50,$A37,Requerimientos!$K$6:$K$50,"Pendiente") -> 3 | E37: =COUNTIFS(Requerimientos!$B$6:$B$50,$A37,Requerimientos!$K$6:$K$50,"Hecho") -> 0 | F37: =IFERROR($E37/$B37,0) -> 0
A38: M10 Calidad | B38: =COUNTIF(Requerimientos!$B$6:$B$50,$A38) -> 9 | C38: =COUNTIFS(Requerimientos!$B$6:$B$50,$A38,Requerimientos!$G$6:$G$50,"Alta") -> 8 | D38: =COUNTIFS(Requerimientos!$B$6:$B$50,$A38,Requerimientos!$K$6:$K$50,"Pendiente") -> 9 | E38: =COUNTIFS(Requerimientos!$B$6:$B$50,$A38,Requerimientos!$K$6:$K$50,"Hecho") -> 0 | F38: =IFERROR($E38/$B38,0) -> 0

Sheet Requerimientos
A1: RoomTrip · Matriz de requerimientos
A2: 1TEL05 Servicios y Aplicaciones para IoT · PUCP · Semestre 2026-2
A3: Esta hoja es la única fuente de datos. Las hojas «Por rol» y «Por entregable» la reflejan mediante fórmulas: editar aquí y allá se actualiza solo.
A5: ID | B5: Módulo | C5: Rol | D5: Tipo | E5: Requerimiento | F5: Criterio de aceptación | G5: Prioridad | H5: Entregable | I5: Foco técnico | J5: Depende de | K5: Estado | L5: Mockup | M5: Responsable | N5: Observaciones
A6: RF-SA-01 | B6: M2 Gestión de usuarios | C6: Superadmin | D6: Funcional | E6: Activar y desactivar administradores de hotel taxistas y clientes | F6: Al desactivar un usuario este no puede iniciar sesión y al reactivarlo recupera el acceso | G6: Alta | H6: Lab 6 | I6: Firebase Authentication | K6: Pendiente | L6: No
A7: RF-SA-02 | B7: M2 Gestión de usuarios | C7: Superadmin | D7: Funcional | E7: Registrar hoteles y asignar un administrador a cada uno | F7: Un hotel registrado queda asociado a exactamente un administrador que ve solo ese hotel | G7: Alta | H7: Lab 6 | I7: Firebase Database | K7: Pendiente | L7: No
A8: RF-SA-04 | B8: M9 Reportes y logs | C8: Superadmin | D8: Funcional | E8: Generar el reporte de reservas por hotel | F8: El reporte agrupa las reservas por hotel | G8: Media | H8: Lab 7 | I8: Presentación prefinal | J8: RF-CL-03 | K8: Pendiente | L8: No
A9: RF-SA-05 | B9: M9 Reportes y logs | C9: Superadmin | D9: Funcional | E9: Consultar el visor de logs de eventos del sistema | F9: El Superadmin ve los eventos registrados con fecha actor y tipo de evento | G9: Media | H9: Lab 7 | I9: Presentación prefinal | J9: RNF-04 | K9: Pendiente | L9: No
A10: RF-SA-03 | B10: M2 Gestión de usuarios | C10: Superadmin | D10: Funcional | E10: Aprobar o habilitar taxistas desde la app web | F10: El taxista pasa de pendiente a habilitado y recién entonces aparece como disponible | G10: Alta | H10: Final | I10: App web de taxistas | J10: RF-TX-01 | K10: Pendiente | L10: No
A11: RF-AH-03 | B11: M3 Catálogo | C11: Administrador de hotel | D11: Funcional | E11: Registrar habitaciones con tipo capacidad de adultos y niños y tamaño en m2 | F11: La habitación guardada muestra los 4 datos y queda listada en el hotel | G11: Alta | H11: Lab 4 | I11: RecyclerView | J11: RF-SA-02 | K11: Pendiente | L11: Sí
A12: RF-AH-04 | B12: M3 Catálogo | C12: Administrador de hotel | D12: Funcional | E12: Registrar servicios con nombre descripción precio imágenes y si tienen costo | F12: Un servicio marcado sin costo no suma al total de la reserva | G12: Alta | H12: Lab 4 | I12: RecyclerView | J12: RF-SA-02 | K12: Pendiente | L12: Sí
A13: RF-AH-02 | B13: M3 Catálogo | C13: Administrador de hotel | D13: Funcional | E13: Subir fotos del hotel con un mínimo de 4 | F13: El formulario no permite guardar con menos de 4 fotos | G13: Alta | H13: Lab 5 | I13: Storage local | J13: RF-SA-02 | K13: Pendiente | L13: Sí
A14: RF-AH-06 | B14: M5 Pagos y cobros | C14: Administrador de hotel | D14: Funcional | E14: Recibir la alerta de checkout y procesar el cobro de la tarjeta registrada | F14: Al hacer checkout el cliente el hotel recibe la alerta y puede ejecutar el cobro | G14: Alta | H14: Lab 5 | I14: Notificaciones | J14: RF-CL-04 | K14: Pendiente | L14: Sí
A15: RF-AH-01 | B15: M3 Catálogo | C15: Administrador de hotel | D15: Funcional | E15: Registrar la ubicación del hotel y los lugares históricos cercanos | F15: La ubicación se selecciona en un mapa y se listan los lugares históricos cercanos asociados | G15: Alta | H15: Lab 6 | I15: Firebase Database | J15: RF-SA-02 | K15: Pendiente | L15: No | N15: Los lugares históricos cercanos aún no están en el mockup.
A16: RF-AH-09 | B16: M7 Chat | C16: Administrador de hotel | D16: Funcional | E16: Responder los chats de clientes con reserva activa | F16: El hotel ve solo los chats de reservas activas y puede responder | G16: Alta | H16: Lab 6 | I16: Firebase Database | J16: RF-CL-07 | K16: Pendiente | L16: Sí
A17: RF-AH-07 | B17: M5 Pagos y cobros | C17: Administrador de hotel | D17: Funcional | E17: Añadir cobros adicionales por daños con monto motivo y observación | F17: El cobro adicional exige los 3 campos y se suma al total de la reserva | G17: Media | H17: Lab 6 | I17: Firebase Database | J17: RF-AH-06 | K17: Pendiente | L17: Sí
A18: RF-AH-05 | B18: M8 Taxi | C18: Administrador de hotel | D18: Funcional | E18: Ver el estado del taxista asignado en camino a recoger y llegó al destino | F18: El hotel ve el estado actualizado del servicio de taxi de sus huéspedes | G18: Media | H18: Lab 7 | I18: Presentación prefinal | J18: RF-TX-06 | K18: Pendiente | L18: Sí
A19: RF-AH-08 | B19: M9 Reportes y logs | C19: Administrador de hotel | D19: Funcional | E19: Reporte de ingresos por servicios adicionales ordenado de menor a mayor | F19: El reporte lista los servicios ordenados ascendentemente por monto total generado | G19: Media | H19: Lab 7 | I19: Presentación prefinal | J19: RF-AH-04 | K19: Pendiente | L19: Parcial | N19: El mockup existe pero el orden del reporte debe invertirse a menor → mayor.
A20: RF-TX-02 | B20: M1 Autenticación | C20: Taxista | D20: Funcional | E20: Acceder a la app móvil una vez habilitado | F20: Un taxista no habilitado no puede iniciar sesión en la app móvil y uno habilitado sí | G20: Alta | H20: Lab 6 | I20: Firebase Authentication | J20: RF-SA-03 | K20: Pendiente | L20: No
A21: RF-TX-03 | B21: M8 Taxi | C21: Taxista | D21: Funcional | E21: Ver hoteles y pedidos disponibles | F21: El taxista habilitado ve la lista de pedidos en estado SOLICITADO | G21: Alta | H21: Lab 7 | I21: Presentación prefinal | J21: RF-CL-08 | K21: Pendiente | L21: No
A22: RF-TX-04 | B22: M8 Taxi | C22: Taxista | D22: Funcional | E22: Aceptar un pedido que deja de estar disponible para los demás | F22: Al aceptar el servicio pasa a ASIGNADO y desaparece de la lista de los otros taxistas | G22: Alta | H22: Lab 7 | I22: Presentación prefinal | J22: RF-TX-03 | K22: Pendiente | L22: No | N22: Requiere transacción para garantizar la exclusividad del pedido.
A23: RF-TX-05 | B23: M8 Taxi | C23: Taxista | D23: Funcional | E23: Registrar automáticamente su ubicación durante el servicio activo | F23: Con un servicio activo la ubicación se actualiza periódicamente sin intervención del taxista | G23: Alta | H23: Lab 7 | I23: Presentación prefinal | J23: RF-TX-04 | K23: Pendiente | L23: No
A24: RF-TX-06 | B24: M8 Taxi | C24: Taxista | D24: Funcional | E24: Actualizar los estados del servicio | F24: El taxista avanza el servicio por SOLICITADO ASIGNADO EN_CAMINO EN_TRASLADO y FINALIZADO | G24: Alta | H24: Lab 7 | I24: Presentación prefinal | J24: RF-TX-04 | K24: Pendiente | L24: No
A25: RF-TX-07 | B25: M8 Taxi | C25: Taxista | D25: Funcional | E25: Registrar FINALIZADO únicamente escaneando el QR del cliente | F25: El estado FINALIZADO no se puede fijar manualmente y solo se alcanza por escaneo del QR | G25: Alta | H25: Lab 7 | I25: Presentación prefinal | J25: RF-CL-10 | K25: Pendiente | L25: No | N25: Necesita librería de escaneo de QR.
A26: RF-TX-01 | B26: M1 Autenticación | C26: Taxista | D26: Funcional | E26: Autoregistrarse en la app web con todos sus datos y fotos | F26: El formulario web exige nombres apellidos tipo y número de documento fecha de nacimiento correo teléfono domicilio foto placa y foto del vehículo | G26: Alta | H26: Final | I26: App web de taxistas | K26: Pendiente | L26: No
A27: RF-CL-02 | B27: M3 Catálogo | C27: Cliente | D27: Funcional | E27: Consultar hoteles habitaciones servicios disponibilidad y valoraciones | F27: El listado muestra hoteles con sus fotos habitaciones servicios y promedio de valoraciones | G27: Alta | H27: Lab 4 | I27: RecyclerView | J27: RF-AH-01 | K27: Pendiente | L27: Sí
A28: RF-CL-06 | B28: M4 Reservas | C28: Cliente | D28: Funcional | E28: Ver el historial de sus reservas | F28: El historial lista las reservas del cliente autenticado con fechas hotel habitación estado y monto | G28: Media | H28: Lab 4 | I28: RecyclerView | J28: RF-CL-03 | K28: Pendiente | L28: Sí
A29: RF-CL-05 | B29: M5 Pagos y cobros | C29: Cliente | D29: Funcional | E29: Recibir notificación cuando se le hace el cobro | F29: El cliente recibe una notificación push con el monto cobrado | G29: Alta | H29: Lab 5 | I29: Notificaciones | J29: RF-AH-06 | K29: Pendiente | L29: Parcial | N29: Requiere Firebase Cloud Messaging.
A30: RF-CL-01 | B30: M1 Autenticación | C30: Cliente | D30: Funcional | E30: Autoregistrarse y quedar habilitado automáticamente | F30: Al completar el formulario con nombres apellidos tipo y número de documento fecha de nacimiento correo teléfono domicilio y foto la cuenta queda activa sin aprobación | G30: Alta | H30: Lab 6 | I30: Firebase Authentication | K30: Pendiente | L30: Parcial | N30: Faltan en el mockup el tipo de documento y la fecha de nacimiento.
A31: RF-CL-03 | B31: M4 Reservas | C31: Cliente | D31: Funcional | E31: Reservar con tarjeta de crédito o débito simulada | F31: Tras confirmar el pago simulado la reserva queda creada y visible en el historial | G31: Alta | H31: Lab 6 | I31: Firebase Database | J31: RF-CL-02 | K31: Pendiente | L31: Sí
A32: RF-CL-04 | B32: M6 Checkout y valoraciones | C32: Cliente | D32: Funcional | E32: Hacer checkout y registrar valoración y observaciones obligatorias | F32: No se puede completar el checkout sin valoración y observaciones | G32: Alta | H32: Lab 6 | I32: Firebase Database | J32: RF-CL-03 | K32: Pendiente | L32: Sí
A33: RF-CL-07 | B33: M7 Chat | C33: Cliente | D33: Funcional | E33: Chat privado con el hotel entre la confirmación de la reserva y el fin del checkout | F33: El chat no está disponible antes de confirmar la reserva ni después del checkout | G33: Alta | H33: Lab 6 | I33: Firebase Database | J33: RF-CL-03 | K33: Pendiente | L33: Parcial | N33: Falta enganchar el chat al bottom navigation.
A34: RF-CL-08 | B34: M8 Taxi | C34: Cliente | D34: Funcional | E34: Solicitar el taxi gratuito al aeropuerto si la reserva alcanza el monto mínimo | F34: La opción aparece solo si el monto de la reserva alcanza el mínimo del hotel es opcional y el cliente indica el aeropuerto destino | G34: Alta | H34: Lab 7 | I34: Presentación prefinal | J34: RF-CL-04 | K34: Pendiente | L34: No
A35: RF-CL-09 | B35: M8 Taxi | C35: Cliente | D35: Funcional | E35: Ver datos vehículo valoración y ubicación del taxista en un mapa | F35: El cliente ve nombre vehículo placa valoración y la posición del taxista actualizándose en el mapa | G35: Alta | H35: Lab 7 | I35: Presentación prefinal | J35: RF-TX-05 | K35: Pendiente | L35: No | N35: Necesita Google Maps SDK y la ubicación desde Realtime Database.
A36: RF-CL-10 | B36: M8 Taxi | C36: Cliente | D36: Funcional | E36: Recibir el QR del hotel y mostrarlo al llegar | F36: El cliente visualiza un QR asociado al servicio de taxi | G36: Alta | H36: Lab 7 | I36: Presentación prefinal | J36: RF-CL-08 | K36: Pendiente | L36: No
A37: RF-CL-11 | B37: M8 Taxi | C37: Cliente | D37: Funcional | E37: Calificar al taxista al finalizar el servicio | F37: Al pasar el servicio a FINALIZADO la app pide la calificación del taxista | G37: Media | H37: Lab 7 | I37: Presentación prefinal | J37: RF-TX-07 | K37: Pendiente | L37: No
A38: RNF-07 | B38: M10 Calidad | C38: Transversal | D38: No funcional | E38: La app móvil es Android nativa en Java con versión mínima Android 14 API 34 | F38: El proyecto compila con minSdk 34 y está escrito en Java | G38: Alta | H38: Lab 3 | I38: Navegación y UI | K38: Pendiente | L38: NA
A39: RF-GN-01 | B39: M4 Reservas | C39: Transversal | D39: Funcional | E39: Una habitación no puede tener reservas de distintos clientes con períodos superpuestos | F39: Al intentar reservar fechas que se solapan con una reserva existente de esa habitación el sistema rechaza la operación | G39: Alta | H39: Lab 6 | I39: Firebase Database | J39: RF-CL-03 | K39: Pendiente | L39: Sí | N39: Validar con una transacción; no basta con comprobarlo en el cliente.
A40: RF-GN-02 | B40: M4 Reservas | C40: Transversal | D40: Funcional | E40: Un mismo cliente no puede tener reservas con fechas de alojamiento superpuestas | F40: Al intentar una segunda reserva que se solapa con otra propia el sistema la rechaza | G40: Alta | H40: Lab 6 | I40: Firebase Database | J40: RF-CL-03 | K40: Pendiente | L40: Sí | N40: Validar con una transacción; no basta con comprobarlo en el cliente.
A41: RF-GN-03 | B41: M1 Autenticación | C41: Transversal | D41: Funcional | E41: Login único: tras autenticar se resuelve el rol y se navega al flujo correspondiente | F41: Con credenciales válidas de cada uno de los 4 roles la app abre el grafo de navegación propio de ese rol | G41: Alta | H41: Lab 6 | I41: Firebase Authentication | K41: Pendiente | L41: Sí
...

Sheet Por rol
A1: RoomTrip · Requerimientos agrupados por rol
A2: Vista de lectura. El contenido se trae por fórmula desde la hoja Requerimientos
A3: Para modificar un requerimiento, edítalo en la hoja «Requerimientos».
A5: ID | B5: Requerimiento | C5: Módulo | D5: Prioridad | E5: Entregable | F5: Estado | G5: Mockup | H5: Responsable
A6: Superadmin · 5 requerimientos
A7: RF-SA-01 | B7: =IFERROR(INDEX(Requerimientos!$E:$E,MATCH($A7,Requerimientos!$A:$A,0)),"") -> Activar y desactivar administradores de hotel taxistas y clientes | C7: =IFERROR(INDEX(Requerimientos!$B:$B,MATCH($A7,Requerimientos!$A:$A,0)),"") -> M2 Gestión de usuarios | D7: =IFERROR(INDEX(Requerimientos!$G:$G,MATCH($A7,Requerimientos!$A:$A,0)),"") -> Alta | E7: =IFERROR(INDEX(Requerimientos!$H:$H,MATCH($A7,Requerimientos!$A:$A,0)),"") -> Lab 6 | F7: =IFERROR(INDEX(Requerimientos!$K:$K,MATCH($A7,Requerimientos!$A:$A,0)),"") -> Pendiente | G7: =IFERROR(INDEX(Requerimientos!$L:$L,MATCH($A7,Requerimientos!$A:$A,0)),"") -> No | H7: =IFERROR(INDEX(Requerimientos!$M:$M,MATCH($A7,Requerimientos!$A:$A,0)),"") -> 0
A8: RF-SA-02 | B8: =IFERROR(INDEX(Requerimientos!$E:$E,MATCH($A8,Requerimientos!$A:$A,0)),"") -> Registrar hoteles y asignar un administrador a cada uno | C8: =IFERROR(INDEX(Requerimientos!$B:$B,MATCH($A8,Requerimientos!$A:$A,0)),"") -> M2 Gestión de usuarios | D8: =IFERROR(INDEX(Requerimientos!$G:$G,MATCH($A8,Requerimientos!$A:$A,0)),"") -> Alta | E8: =IFERROR(INDEX(Requerimientos!$H:$H,MATCH($A8,Requerimientos!$A:$A,0)),"") -> Lab 6 | F8: =IFERROR(INDEX(Requerimientos!$K:$K,MATCH($A8,Requerimientos!$A:$A,0)),"") -> Pendiente | G8: =IFERROR(INDEX(Requerimientos!$L:$L,MATCH($A8,Requerimientos!$A:$A,0)),"") -> No | H8: =IFERROR(INDEX(Requerimientos!$M:$M,MATCH($A8,Requerimientos!$A:$A,0)),"") -> 0
A9: RF-SA-04 | B9: =IFERROR(INDEX(Requerimientos!$E:$E,MATCH($A9,Requerimientos!$A:$A,0)),"") -> Generar el reporte de reservas por hotel | C9: =IFERROR(INDEX(Requerimientos!$B:$B,MATCH($A9,Requerimientos!$A:$A,0)),"") -> M9 Reportes y logs | D9: =IFERROR(INDEX(Requerimientos!$G:$G,MATCH($A9,Requerimientos!$A:$A,0)),"") -> Media | E9: =IFERROR(INDEX(Requerimientos!$H:$H,MATCH($A9,Requerimientos!$A:$A,0)),"") -> Lab 7 | F9: =IFERROR(INDEX(Requerimientos!$K:$K,MATCH($A9,Requerimientos!$A:$A,0)),"") -> Pendiente | G9: =IFERROR(INDEX(Requerimientos!$L:$L,MATCH($A9,Requerimientos!$A:$A,0)),"") -> No | H9: =IFERROR(INDEX(Requerimientos!$M:$M,MATCH($A9,Requerimientos!$A:$A,0)),"") -> 0
A10: RF-SA-05 | B10: =IFERROR(INDEX(Requerimientos!$E:$E,MATCH($A10,Requerimientos!$A:$A,0)),"") -> Consultar el visor de logs de eventos del sistema | C10: =IFERROR(INDEX(Requerimientos!$B:$B,MATCH($A10,Requerimientos!$A:$A,0)),"") -> M9 Reportes y logs | D10: =IFERROR(INDEX(Requerimientos!$G:$G,MATCH($A10,Requerimientos!$A:$A,0)),"") -> Media | E10: =IFERROR(INDEX(Requerimientos!$H:$H,MATCH($A10,Requerimientos!$A:$A,0)),"") -> Lab 7 | F10: =IFERROR(INDEX(Requerimientos!$K:$K,MATCH($A10,Requerimientos!$A:$A,0)),"") -> Pendiente | G10: =IFERROR(INDEX(Requerimientos!$L:$L,MATCH($A10,Requerimientos!$A:$A,0)),"") -> No | H10: =IFERROR(INDEX(Requerimientos!$M:$M,MATCH($A10,Requerimientos!$A:$A,0)),"") -> 0
A11: RF-SA-03 | B11: =IFERROR(INDEX(Requerimientos!$E:$E,MATCH($A11,Requerimientos!$A:$A,0)),"") -> Aprobar o habilitar taxistas desde la app web | C11: =IFERROR(INDEX(Requerimientos!$B:$B,MATCH($A11,Requerimientos!$A:$A,0)),"") -> M2 Gestión de usuarios | D11: =IFERROR(INDEX(Requerimientos!$G:$G,MATCH($A11,Requerimientos!$A:$A,0)),"") -> Alta | E11: =IFERROR(INDEX(Requerimientos!$H:$H,MATCH($A11,Requerimientos!$A:$A,0)),"") -> Final | F11: =IFERROR(INDEX(Requerimientos!$K:$K,MATCH($A11,Requerimientos!$A:$A,0)),"") -> Pendiente | G11: =IFERROR(INDEX(Requerimientos!$L:$L,MATCH($A11,Requerimientos!$A:$A,0)),"") -> No | H11: =IFERROR(INDEX(Requerimientos!$M:$M,MATCH($A11,Requerimientos!$A:$A,0)),"") -> 0
A13: Administrador de hotel · 9 requerimientos
A14: RF-AH-03 | B14: =IFERROR(INDEX(Requerimientos!$E:$E,MATCH($A14,Requerimientos!$A:$A,0)),"") -> Registrar habitaciones con tipo capacidad de adultos y niños y tamaño en m2 | C14: =IFERROR(INDEX(Requerimientos!$B:$B,MATCH($A14,Requerimientos!$A:$A,0)),"") -> M3 Catálogo | D14: =IFERROR(INDEX(Requerimientos!$G:$G,MATCH($A14,Requerimientos!$A:$A,0)),"") -> Alta | E14: =IFERROR(INDEX(Requerimientos!$H:$H,MATCH($A14,Requerimientos!$A:$A,0)),"") -> Lab 4 | F14: =IFERROR(INDEX(Requerimientos!$K:$K,MATCH($A14,Requerimientos!$A:$A,0)),"") -> Pendiente | G14: =IFERROR(INDEX(Requerimientos!$L:$L,MATCH($A14,Requerimientos!$A:$A,0)),"") -> Sí | H14: =IFERROR(INDEX(Requerimientos!$M:$M,MATCH($A14,Requerimientos!$A:$A,0)),"") -> 0
A15: RF-AH-04 | B15: =IFERROR(INDEX(Requerimientos!$E:$E,MATCH($A15,Requerimientos!$A:$A,0)),"") -> Registrar servicios con nombre descripción precio imágenes y si tienen costo | C15: =IFERROR(INDEX(Requerimientos!$B:$B,MATCH($A15,Requerimientos!$A:$A,0)),"") -> M3 Catálogo | D15: =IFERROR(INDEX(Requerimientos!$G:$G,MATCH($A15,Requerimientos!$A:$A,0)),"") -> Alta | E15: =IFERROR(INDEX(Requerimientos!$H:$H,MATCH($A15,Requerimientos!$A:$A,0)),"") -> Lab 4 | F15: =IFERROR(INDEX(Requerimientos!$K:$K,MATCH($A15,Requerimientos!$A:$A,0)),"") -> Pendiente | G15: =IFERROR(INDEX(Requerimientos!$L:$L,MATCH($A15,Requerimientos!$A:$A,0)),"") -> Sí | H15: =IFERROR(INDEX(Requerimientos!$M:$M,MATCH($A15,Requerimientos!$A:$A,0)),"") -> 0
A16: RF-AH-02 | B16: =IFERROR(INDEX(Requerimientos!$E:$E,MATCH($A16,Requerimientos!$A:$A,0)),"") -> Subir fotos del hotel con un mínimo de 4 | C16: =IFERROR(INDEX(Requerimientos!$B:$B,MATCH($A16,Requerimientos!$A:$A,0)),"") -> M3 Catálogo | D16: =IFERROR(INDEX(Requerimientos!$G:$G,MATCH($A16,Requerimientos!$A:$A,0)),"") -> Alta | E16: =IFERROR(INDEX(Requerimientos!$H:$H,MATCH($A16,Requerimientos!$A:$A,0)),"") -> Lab 5 | F16: =IFERROR(INDEX(Requerimientos!$K:$K,MATCH($A16,Requerimientos!$A:$A,0)),"") -> Pendiente | G16: =IFERROR(INDEX(Requerimientos!$L:$L,MATCH($A16,Requerimientos!$A:$A,0)),"") -> Sí | H16: =IFERROR(INDEX(Requerimientos!$M:$M,MATCH($A16,Requerimientos!$A:$A,0)),"") -> 0
A17: RF-AH-06 | B17: =IFERROR(INDEX(Requerimientos!$E:$E,MATCH($A17,Requerimientos!$A:$A,0)),"") -> Recibir la alerta de checkout y procesar el cobro de la tarjeta registrada | C17: =IFERROR(INDEX(Requerimientos!$B:$B,MATCH($A17,Requerimientos!$A:$A,0)),"") -> M5 Pagos y cobros | D17: =IFERROR(INDEX(Requerimientos!$G:$G,MATCH($A17,Requerimientos!$A:$A,0)),"") -> Alta | E17: =IFERROR(INDEX(Requerimientos!$H:$H,MATCH($A17,Requerimientos!$A:$A,0)),"") -> Lab 5 | F17: =IFERROR(INDEX(Requerimientos!$K:$K,MATCH($A17,Requerimientos!$A:$A,0)),"") -> Pendiente | G17: =IFERROR(INDEX(Requerimientos!$L:$L,MATCH($A17,Requerimientos!$A:$A,0)),"") -> Sí | H17: =IFERROR(INDEX(Requerimientos!$M:$M,MATCH($A17,Requerimientos!$A:$A,0)),"") -> 0
A18: RF-AH-01 | B18: =IFERROR(INDEX(Requerimientos!$E:$E,MATCH($A18,Requerimientos!$A:$A,0)),"") -> Registrar la ubicación del hotel y los lugares históricos cercanos | C18: =IFERROR(INDEX(Requerimientos!$B:$B,MATCH($A18,Requerimientos!$A:$A,0)),"") -> M3 Catálogo | D18: =IFERROR(INDEX(Requerimientos!$G:$G,MATCH($A18,Requerimientos!$A:$A,0)),"") -> Alta | E18: =IFERROR(INDEX(Requerimientos!$H:$H,MATCH($A18,Requerimientos!$A:$A,0)),"") -> Lab 6 | F18: =IFERROR(INDEX(Requerimientos!$K:$K,MATCH($A18,Requerimientos!$A:$A,0)),"") -> Pendiente | G18: =IFERROR(INDEX(Requerimientos!$L:$L,MATCH($A18,Requerimientos!$A:$A,0)),"") -> No | H18: =IFERROR(INDEX(Requerimientos!$M:$M,MATCH($A18,Requerimientos!$A:$A,0)),"") -> 0
A19: RF-AH-09 | B19: =IFERROR(INDEX(Requerimientos!$E:$E,MATCH($A19,Requerimientos!$A:$A,0)),"") -> Responder los chats de clientes con reserva activa | C19: =IFERROR(INDEX(Requerimientos!$B:$B,MATCH($A19,Requerimientos!$A:$A,0)),"") -> M7 Chat | D19: =IFERROR(INDEX(Requerimientos!$G:$G,MATCH($A19,Requerimientos!$A:$A,0)),"") -> Alta | E19: =IFERROR(INDEX(Requerimientos!$H:$H,MATCH($A19,Requerimientos!$A:$A,0)),"") -> Lab 6 | F19: =IFERROR(INDEX(Requerimientos!$K:$K,MATCH($A19,Requerimientos!$A:$A,0)),"") -> Pendiente | G19: =IFERROR(INDEX(Requerimientos!$L:$L,MATCH($A19,Requerimientos!$A:$A,0)),"") -> Sí | H19: =IFERROR(INDEX(Requerimientos!$M:$M,MATCH($A19,Requerimientos!$A:$A,0)),"") -> 0
A20: RF-AH-07 | B20: =IFERROR(INDEX(Requerimientos!$E:$E,MATCH($A20,Requerimientos!$A:$A,0)),"") -> Añadir cobros adicionales por daños con monto motivo y observación | C20: =IFERROR(INDEX(Requerimientos!$B:$B,MATCH($A20,Requerimientos!$A:$A,0)),"") -> M5 Pagos y cobros | D20: =IFERROR(INDEX(Requerimientos!$G:$G,MATCH($A20,Requerimientos!$A:$A,0)),"") -> Media | E20: =IFERROR(INDEX(Requerimientos!$H:$H,MATCH($A20,Requerimientos!$A:$A,0)),"") -> Lab 6 | F20: =IFERROR(INDEX(Requerimientos!$K:$K,MATCH($A20,Requerimientos!$A:$A,0)),"") -> Pendiente | G20: =IFERROR(INDEX(Requerimientos!$L:$L,MATCH($A20,Requerimientos!$A:$A,0)),"") -> Sí | H20: =IFERROR(INDEX(Requerimientos!$M:$M,MATCH($A20,Requerimientos!$A:$A,0)),"") -> 0
A21: RF-AH-05 | B21: =IFERROR(INDEX(Requerimientos!$E:$E,MATCH($A21,Requerimientos!$A:$A,0)),"") -> Ver el estado del taxista asignado en camino a recoger y llegó al destino | C21: =IFERROR(INDEX(Requerimientos!$B:$B,MATCH($A21,Requerimientos!$A:$A,0)),"") -> M8 Taxi | D21: =IFERROR(INDEX(Requerimientos!$G:$G,MATCH($A21,Requerimientos!$A:$A,0)),"") -> Media | E21: =IFERROR(INDEX(Requerimientos!$H:$H,MATCH($A21,Requerimientos!$A:$A,0)),"") -> Lab 7 | F21: =IFERROR(INDEX(Requerimientos!$K:$K,MATCH($A21,Requerimientos!$A:$A,0)),"") -> Pendiente | G21: =IFERROR(INDEX(Requerimientos!$L:$L,MATCH($A21,Requerimientos!$A:$A,0)),"") -> Sí | H21: =IFERROR(INDEX(Requerimientos!$M:$M,MATCH($A21,Requerimientos!$A:$A,0)),"") -> 0
A22: RF-AH-08 | B22: =IFERROR(INDEX(Requerimientos!$E:$E,MATCH($A22,Requerimientos!$A:$A,0)),"") -> Reporte de ingresos por servicios adicionales ordenado de menor a mayor | C22: =IFERROR(INDEX(Requerimientos!$B:$B,MATCH($A22,Requerimientos!$A:$A,0)),"") -> M9 Reportes y logs | D22: =IFERROR(INDEX(Requerimientos!$G:$G,MATCH($A22,Requerimientos!$A:$A,0)),"") -> Media | E22: =IFERROR(INDEX(Requerimientos!$H:$H,MATCH($A22,Requerimientos!$A:$A,0)),"") -> Lab 7 | F22: =IFERROR(INDEX(Requerimientos!$K:$K,MATCH($A22,Requerimientos!$A:$A,0)),"") -> Pendiente | G22: =IFERROR(INDEX(Requerimientos!$L:$L,MATCH($A22,Requerimientos!$A:$A,0)),"") -> Parcial | H22: =IFERROR(INDEX(Requerimientos!$M:$M,MATCH($A22,Requerimientos!$A:$A,0)),"") -> 0
A24: Taxista · 7 requerimientos
A25: RF-TX-02 | B25: =IFERROR(INDEX(Requerimientos!$E:$E,MATCH($A25,Requerimientos!$A:$A,0)),"") -> Acceder a la app móvil una vez habilitado | C25: =IFERROR(INDEX(Requerimientos!$B:$B,MATCH($A25,Requerimientos!$A:$A,0)),"") -> M1 Autenticación | D25: =IFERROR(INDEX(Requerimientos!$G:$G,MATCH($A25,Requerimientos!$A:$A,0)),"") -> Alta | E25: =IFERROR(INDEX(Requerimientos!$H:$H,MATCH($A25,Requerimientos!$A:$A,0)),"") -> Lab 6 | F25: =IFERROR(INDEX(Requerimientos!$K:$K,MATCH($A25,Requerimientos!$A:$A,0)),"") -> Pendiente | G25: =IFERROR(INDEX(Requerimientos!$L:$L,MATCH($A25,Requerimientos!$A:$A,0)),"") -> No | H25: =IFERROR(INDEX(Requerimientos!$M:$M,MATCH($A25,Requerimientos!$A:$A,0)),"") -> 0
A26: RF-TX-03 | B26: =IFERROR(INDEX(Requerimientos!$E:$E,MATCH($A26,Requerimientos!$A:$A,0)),"") -> Ver hoteles y pedidos disponibles | C26: =IFERROR(INDEX(Requerimientos!$B:$B,MATCH($A26,Requerimientos!$A:$A,0)),"") -> M8 Taxi | D26: =IFERROR(INDEX(Requerimientos!$G:$G,MATCH($A26,Requerimientos!$A:$A,0)),"") -> Alta | E26: =IFERROR(INDEX(Requerimientos!$H:$H,MATCH($A26,Requerimientos!$A:$A,0)),"") -> Lab 7 | F26: =IFERROR(INDEX(Requerimientos!$K:$K,MATCH($A26,Requerimientos!$A:$A,0)),"") -> Pendiente | G26: =IFERROR(INDEX(Requerimientos!$L:$L,MATCH($A26,Requerimientos!$A:$A,0)),"") -> No | H26: =IFERROR(INDEX(Requerimientos!$M:$M,MATCH($A26,Requerimientos!$A:$A,0)),"") -> 0
A27: RF-TX-04 | B27: =IFERROR(INDEX(Requerimientos!$E:$E,MATCH($A27,Requerimientos!$A:$A,0)),"") -> Aceptar un pedido que deja de estar disponible para los demás | C27: =IFERROR(INDEX(Requerimientos!$B:$B,MATCH($A27,Requerimientos!$A:$A,0)),"") -> M8 Taxi | D27: =IFERROR(INDEX(Requerimientos!$G:$G,MATCH($A27,Requerimientos!$A:$A,0)),"") -> Alta | E27: =IFERROR(INDEX(Requerimientos!$H:$H,MATCH($A27,Requerimientos!$A:$A,0)),"") -> Lab 7 | F27: =IFERROR(INDEX(Requerimientos!$K:$K,MATCH($A27,Requerimientos!$A:$A,0)),"") -> Pendiente | G27: =IFERROR(INDEX(Requerimientos!$L:$L,MATCH($A27,Requerimientos!$A:$A,0)),"") -> No | H27: =IFERROR(INDEX(Requerimientos!$M:$M,MATCH($A27,Requerimientos!$A:$A,0)),"") -> 0
A28: RF-TX-05 | B28: =IFERROR(INDEX(Requerimientos!$E:$E,MATCH($A28,Requerimientos!$A:$A,0)),"") -> Registrar automáticamente su ubicación durante el servicio activo | C28: =IFERROR(INDEX(Requerimientos!$B:$B,MATCH($A28,Requerimientos!$A:$A,0)),"") -> M8 Taxi | D28: =IFERROR(INDEX(Requerimientos!$G:$G,MATCH($A28,Requerimientos!$A:$A,0)),"") -> Alta | E28: =IFERROR(INDEX(Requerimientos!$H:$H,MATCH($A28,Requerimientos!$A:$A,0)),"") -> Lab 7 | F28: =IFERROR(INDEX(Requerimientos!$K:$K,MATCH($A28,Requerimientos!$A:$A,0)),"") -> Pendiente | G28: =IFERROR(INDEX(Requerimientos!$L:$L,MATCH($A28,Requerimientos!$A:$A,0)),"") -> No | H28: =IFERROR(INDEX(Requerimientos!$M:$M,MATCH($A28,Requerimientos!$A:$A,0)),"") -> 0
A29: RF-TX-06 | B29: =IFERROR(INDEX(Requerimientos!$E:$E,MATCH($A29,Requerimientos!$A:$A,0)),"") -> Actualizar los estados del servicio | C29: =IFERROR(INDEX(Requerimientos!$B:$B,MATCH($A29,Requerimientos!$A:$A,0)),"") -> M8 Taxi | D29: =IFERROR(INDEX(Requerimientos!$G:$G,MATCH($A29,Requerimientos!$A:$A,0)),"") -> Alta | E29: =IFERROR(INDEX(Requerimientos!$H:$H,MATCH($A29,Requerimientos!$A:$A,0)),"") -> Lab 7 | F29: =IFERROR(INDEX(Requerimientos!$K:$K,MATCH($A29,Requerimientos!$A:$A,0)),"") -> Pendiente | G29: =IFERROR(INDEX(Requerimientos!$L:$L,MATCH($A29,Requerimientos!$A:$A,0)),"") -> No | H29: =IFERROR(INDEX(Requerimientos!$M:$M,MATCH($A29,Requerimientos!$A:$A,0)),"") -> 0
A30: RF-TX-07 | B30: =IFERROR(INDEX(Requerimientos!$E:$E,MATCH($A30,Requerimientos!$A:$A,0)),"") -> Registrar FINALIZADO únicamente escaneando el QR del cliente | C30: =IFERROR(INDEX(Requerimientos!$B:$B,MATCH($A30,Requerimientos!$A:$A,0)),"") -> M8 Taxi | D30: =IFERROR(INDEX(Requerimientos!$G:$G,MATCH($A30,Requerimientos!$A:$A,0)),"") -> Alta | E30: =IFERROR(INDEX(Requerimientos!$H:$H,MATCH($A30,Requerimientos!$A:$A,0)),"") -> Lab 7 | F30: =IFERROR(INDEX(Requerimientos!$K:$K,MATCH($A30,Requerimientos!$A:$A,0)),"") -> Pendiente | G30: =IFERROR(INDEX(Requerimientos!$L:$L,MATCH($A30,Requerimientos!$A:$A,0)),"") -> No | H30: =IFERROR(INDEX(Requerimientos!$M:$M,MATCH($A30,Requerimientos!$A:$A,0)),"") -> 0
A31: RF-TX-01 | B31: =IFERROR(INDEX(Requerimientos!$E:$E,MATCH($A31,Requerimientos!$A:$A,0)),"") -> Autoregistrarse en la app web con todos sus datos y fotos | C31: =IFERROR(INDEX(Requerimientos!$B:$B,MATCH($A31,Requerimientos!$A:$A,0)),"") -> M1 Autenticación | D31: =IFERROR(INDEX(Requerimientos!$G:$G,MATCH($A31,Requerimientos!$A:$A,0)),"") -> Alta | E31: =IFERROR(INDEX(Requerimientos!$H:$H,MATCH($A31,Requerimientos!$A:$A,0)),"") -> Final | F31: =IFERROR(INDEX(Requerimientos!$K:$K,MATCH($A31,Requerimientos!$A:$A,0)),"") -> Pendiente | G31: =IFERROR(INDEX(Requerimientos!$L:$L,MATCH($A31,Requerimientos!$A:$A,0)),"") -> No | H31: =IFERROR(INDEX(Requerimientos!$M:$M,MATCH($A31,Requerimientos!$A:$A,0)),"") -> 0
A33: Cliente · 11 requerimientos
A34: RF-CL-02 | B34: =IFERROR(INDEX(Requerimientos!$E:$E,MATCH($A34,Requerimientos!$A:$A,0)),"") -> Consultar hoteles habitaciones servicios disponibilidad y valoraciones | C34: =IFERROR(INDEX(Requerimientos!$B:$B,MATCH($A34,Requerimientos!$A:$A,0)),"") -> M3 Catálogo | D34: =IFERROR(INDEX(Requerimientos!$G:$G,MATCH($A34,Requerimientos!$A:$A,0)),"") -> Alta | E34: =IFERROR(INDEX(Requerimientos!$H:$H,MATCH($A34,Requerimientos!$A:$A,0)),"") -> Lab 4 | F34: =IFERROR(INDEX(Requerimientos!$K:$K,MATCH($A34,Requerimientos!$A:$A,0)),"") -> Pendiente | G34: =IFERROR(INDEX(Requerimientos!$L:$L,MATCH($A34,Requerimientos!$A:$A,0)),"") -> Sí | H34: =IFERROR(INDEX(Requerimientos!$M:$M,MATCH($A34,Requerimientos!$A:$A,0)),"") -> 0
A35: RF-CL-06 | B35: =IFERROR(INDEX(Requerimientos!$E:$E,MATCH($A35,Requerimientos!$A:$A,0)),"") -> Ver el historial de sus reservas | C35: =IFERROR(INDEX(Requerimientos!$B:$B,MATCH($A35,Requerimientos!$A:$A,0)),"") -> M4 Reservas | D35: =IFERROR(INDEX(Requerimientos!$G:$G,MATCH($A35,Requerimientos!$A:$A,0)),"") -> Media | E35: =IFERROR(INDEX(Requerimientos!$H:$H,MATCH($A35,Requerimientos!$A:$A,0)),"") -> Lab 4 | F35: =IFERROR(INDEX(Requerimientos!$K:$K,MATCH($A35,Requerimientos!$A:$A,0)),"") -> Pendiente | G35: =IFERROR(INDEX(Requerimientos!$L:$L,MATCH($A35,Requerimientos!$A:$A,0)),"") -> Sí | H35: =IFERROR(INDEX(Requerimientos!$M:$M,MATCH($A35,Requerimientos!$A:$A,0)),"") -> 0
A36: RF-CL-05 | B36: =IFERROR(INDEX(Requerimientos!$E:$E,MATCH($A36,Requerimientos!$A:$A,0)),"") -> Recibir notificación cuando se le hace el cobro | C36: =IFERROR(INDEX(Requerimientos!$B:$B,MATCH($A36,Requerimientos!$A:$A,0)),"") -> M5 Pagos y cobros | D36: =IFERROR(INDEX(Requerimientos!$G:$G,MATCH($A36,Requerimientos!$A:$A,0)),"") -> Alta | E36: =IFERROR(INDEX(Requerimientos!$H:$H,MATCH($A36,Requerimientos!$A:$A,0)),"") -> Lab 5 | F36: =IFERROR(INDEX(Requerimientos!$K:$K,MATCH($A36,Requerimientos!$A:$A,0)),"") -> Pendiente | G36: =IFERROR(INDEX(Requerimientos!$L:$L,MATCH($A36,Requerimientos!$A:$A,0)),"") -> Parcial | H36: =IFERROR(INDEX(Requerimientos!$M:$M,MATCH($A36,Requerimientos!$A:$A,0)),"") -> 0
A37: RF-CL-01 | B37: =IFERROR(INDEX(Requerimientos!$E:$E,MATCH($A37,Requerimientos!$A:$A,0)),"") -> Autoregistrarse y quedar habilitado automáticamente | C37: =IFERROR(INDEX(Requerimientos!$B:$B,MATCH($A37,Requerimientos!$A:$A,0)),"") -> M1 Autenticación | D37: =IFERROR(INDEX(Requerimientos!$G:$G,MATCH($A37,Requerimientos!$A:$A,0)),"") -> Alta | E37: =IFERROR(INDEX(Requerimientos!$H:$H,MATCH($A37,Requerimientos!$A:$A,0)),"") -> Lab 6 | F37: =IFERROR(INDEX(Requerimientos!$K:$K,MATCH($A37,Requerimientos!$A:$A,0)),"") -> Pendiente | G37: =IFERROR(INDEX(Requerimientos!$L:$L,MATCH($A37,Requerimientos!$A:$A,0)),"") -> Parcial | H37: =IFERROR(INDEX(Requerimientos!$M:$M,MATCH($A37,Requerimientos!$A:$A,0)),"") -> 0
A38: RF-CL-03 | B38: =IFERROR(INDEX(Requerimientos!$E:$E,MATCH($A38,Requerimientos!$A:$A,0)),"") -> Reservar con tarjeta de crédito o débito simulada | C38: =IFERROR(INDEX(Requerimientos!$B:$B,MATCH($A38,Requerimientos!$A:$A,0)),"") -> M4 Reservas | D38: =IFERROR(INDEX(Requerimientos!$G:$G,MATCH($A38,Requerimientos!$A:$A,0)),"") -> Alta | E38: =IFERROR(INDEX(Requerimientos!$H:$H,MATCH($A38,Requerimientos!$A:$A,0)),"") -> Lab 6 | F38: =IFERROR(INDEX(Requerimientos!$K:$K,MATCH($A38,Requerimientos!$A:$A,0)),"") -> Pendiente | G38: =IFERROR(INDEX(Requerimientos!$L:$L,MATCH($A38,Requerimientos!$A:$A,0)),"") -> Sí | H38: =IFERROR(INDEX(Requerimientos!$M:$M,MATCH($A38,Requerimientos!$A:$A,0)),"") -> 0
A39: RF-CL-04 | B39: =IFERROR(INDEX(Requerimientos!$E:$E,MATCH($A39,Requerimientos!$A:$A,0)),"") -> Hacer checkout y registrar valoración y observaciones obligatorias | C39: =IFERROR(INDEX(Requerimientos!$B:$B,MATCH($A39,Requerimientos!$A:$A,0)),"") -> M6 Checkout y valoraciones | D39: =IFERROR(INDEX(Requerimientos!$G:$G,MATCH($A39,Requerimientos!$A:$A,0)),"") -> Alta | E39: =IFERROR(INDEX(Requerimientos!$H:$H,MATCH($A39,Requerimientos!$A:$A,0)),"") -> Lab 6 | F39: =IFERROR(INDEX(Requerimientos!$K:$K,MATCH($A39,Requerimientos!$A:$A,0)),"") -> Pendiente | G39: =IFERROR(INDEX(Requerimientos!$L:$L,MATCH($A39,Requerimientos!$A:$A,0)),"") -> Sí | H39: =IFERROR(INDEX(Requerimientos!$M:$M,MATCH($A39,Requerimientos!$A:$A,0)),"") -> 0
A40: RF-CL-07 | B40: =IFERROR(INDEX(Requerimientos!$E:$E,MATCH($A40,Requerimientos!$A:$A,0)),"") -> Chat privado con el hotel entre la confirmación de la reserva y el fin del checkout | C40: =IFERROR(INDEX(Requerimientos!$B:$B,MATCH($A40,Requerimientos!$A:$A,0)),"") -> M7 Chat | D40: =IFERROR(INDEX(Requerimientos!$G:$G,MATCH($A40,Requerimientos!$A:$A,0)),"") -> Alta | E40: =IFERROR(INDEX(Requerimientos!$H:$H,MATCH($A40,Requerimientos!$A:$A,0)),"") -> Lab 6 | F40: =IFERROR(INDEX(Requerimientos!$K:$K,MATCH($A40,Requerimientos!$A:$A,0)),"") -> Pendiente | G40: =IFERROR(INDEX(Requerimientos!$L:$L,MATCH($A40,Requerimientos!$A:$A,0)),"") -> Parcial | H40: =IFERROR(INDEX(Requerimientos!$M:$M,MATCH($A40,Requerimientos!$A:$A,0)),"") -> 0
A41: RF-CL-08 | B41: =IFERROR(INDEX(Requerimientos!$E:$E,MATCH($A41,Requerimientos!$A:$A,0)),"") -> Solicitar el taxi gratuito al aeropuerto si la reserva alcanza el monto mínimo | C41: =IFERROR(INDEX(Requerimientos!$B:$B,MATCH($A41,Requerimientos!$A:$A,0)),"") -> M8 Taxi | D41: =IFERROR(INDEX(Requerimientos!$G:$G,MATCH($A41,Requerimientos!$A:$A,0)),"") -> Alta | E41: =IFERROR(INDEX(Requerimientos!$H:$H,MATCH($A41,Requerimientos!$A:$A,0)),"") -> Lab 7 | F41: =IFERROR(INDEX(Requerimientos!$K:$K,MATCH($A41,Requerimientos!$A:$A,0)),"") -> Pendiente | G41: =IFERROR(INDEX(Requerimientos!$L:$L,MATCH($A41,Requerimientos!$A:$A,0)),"") -> No | H41: =IFERROR(INDEX(Requerimientos!$M:$M,MATCH($A41,Requerimientos!$A:$A,0)),"") -> 0
A42: RF-CL-09 | B42: =IFERROR(INDEX(Requerimientos!$E:$E,MATCH($A42,Requerimientos!$A:$A,0)),"") -> Ver datos vehículo valoración y ubicación del taxista en un mapa | C42: =IFERROR(INDEX(Requerimientos!$B:$B,MATCH($A42,Requerimientos!$A:$A,0)),"") -> M8 Taxi | D42: =IFERROR(INDEX(Requerimientos!$G:$G,MATCH($A42,Requerimientos!$A:$A,0)),"") -> Alta | E42: =IFERROR(INDEX(Requerimientos!$H:$H,MATCH($A42,Requerimientos!$A:$A,0)),"") -> Lab 7 | F42: =IFERROR(INDEX(Requerimientos!$K:$K,MATCH($A42,Requerimientos!$A:$A,0)),"") -> Pendiente | G42: =IFERROR(INDEX(Requerimientos!$L:$L,MATCH($A42,Requerimientos!$A:$A,0)),"") -> No | H42: =IFERROR(INDEX(Requerimientos!$M:$M,MATCH($A42,Requerimientos!$A:$A,0)),"") -> 0
A43: RF-CL-10 | B43: =IFERROR(INDEX(Requerimientos!$E:$E,MATCH($A43,Requerimientos!$A:$A,0)),"") -> Recibir el QR del hotel y mostrarlo al llegar | C43: =IFERROR(INDEX(Requerimientos!$B:$B,MATCH($A43,Requerimientos!$A:$A,0)),"") -> M8 Taxi | D43: =IFERROR(INDEX(Requerimientos!$G:$G,MATCH($A43,Requerimientos!$A:$A,0)),"") -> Alta | E43: =IFERROR(INDEX(Requerimientos!$H:$H,MATCH($A43,Requerimientos!$A:$A,0)),"") -> Lab 7 | F43: =IFERROR(INDEX(Requerimientos!$K:$K,MATCH($A43,Requerimientos!$A:$A,0)),"") -> Pendiente | G43: =IFERROR(INDEX(Requerimientos!$L:$L,MATCH($A43,Requerimientos!$A:$A,0)),"") -> No | H43: =IFERROR(INDEX(Requerimientos!$M:$M,MATCH($A43,Requerimientos!$A:$A,0)),"") -> 0
A44: RF-CL-11 | B44: =IFERROR(INDEX(Requerimientos!$E:$E,MATCH($A44,Requerimientos!$A:$A,0)),"") -> Calificar al taxista al finalizar el servicio | C44: =IFERROR(INDEX(Requerimientos!$B:$B,MATCH($A44,Requerimientos!$A:$A,0)),"") -> M8 Taxi | D44: =IFERROR(INDEX(Requerimientos!$G:$G,MATCH($A44,Requerimientos!$A:$A,0)),"") -> Media | E44: =IFERROR(INDEX(Requerimientos!$H:$H,MATCH($A44,Requerimientos!$A:$A,0)),"") -> Lab 7 | F44: =IFERROR(INDEX(Requerimientos!$K:$K,MATCH($A44,Requerimientos!$A:$A,0)),"") -> Pendiente | G44: =IFERROR(INDEX(Requerimientos!$L:$L,MATCH($A44,Requerimientos!$A:$A,0)),"") -> No | H44: =IFERROR(INDEX(Requerimientos!$M:$M,MATCH($A44,Requerimientos!$A:$A,0)),"") -> 0
...

Sheet Por entregable
A1: RoomTrip · Plan por entregable
A2: Qué requerimiento se implementa en cada laboratorio del curso
A3: Vista de lectura. El contenido se trae por fórmula desde la hoja «Requerimientos».
A5: ID | B5: Requerimiento | C5: Rol | D5: Foco técnico | E5: Prioridad | F5: Estado | G5: Mockup | H5: Depende de
A6: Lab 3 · 15/09/2026 · 1 requerimiento
A7: RNF-07 | B7: =IFERROR(INDEX(Requerimientos!$E:$E,MATCH($A7,Requerimientos!$A:$A,0)),"") -> La app móvil es Android nativa en Java con versión mínima Android 14 API 34 | C7: =IFERROR(INDEX(Requerimientos!$C:$C,MATCH($A7,Requerimientos!$A:$A,0)),"") -> Transversal | D7: =IFERROR(INDEX(Requerimientos!$I:$I,MATCH($A7,Requerimientos!$A:$A,0)),"") -> Navegación y UI | E7: =IFERROR(INDEX(Requerimientos!$G:$G,MATCH($A7,Requerimientos!$A:$A,0)),"") -> Alta | F7: =IFERROR(INDEX(Requerimientos!$K:$K,MATCH($A7,Requerimientos!$A:$A,0)),"") -> Pendiente | G7: =IFERROR(INDEX(Requerimientos!$L:$L,MATCH($A7,Requerimientos!$A:$A,0)),"") -> NA | H7: =IFERROR(INDEX(Requerimientos!$J:$J,MATCH($A7,Requerimientos!$A:$A,0)),"") -> 0
A9: Lab 4 · 29/09/2026 · 4 requerimientos
A10: RF-AH-03 | B10: =IFERROR(INDEX(Requerimientos!$E:$E,MATCH($A10,Requerimientos!$A:$A,0)),"") -> Registrar habitaciones con tipo capacidad de adultos y niños y tamaño en m2 | C10: =IFERROR(INDEX(Requerimientos!$C:$C,MATCH($A10,Requerimientos!$A:$A,0)),"") -> Administrador de hotel | D10: =IFERROR(INDEX(Requerimientos!$I:$I,MATCH($A10,Requerimientos!$A:$A,0)),"") -> RecyclerView | E10: =IFERROR(INDEX(Requerimientos!$G:$G,MATCH($A10,Requerimientos!$A:$A,0)),"") -> Alta | F10: =IFERROR(INDEX(Requerimientos!$K:$K,MATCH($A10,Requerimientos!$A:$A,0)),"") -> Pendiente | G10: =IFERROR(INDEX(Requerimientos!$L:$L,MATCH($A10,Requerimientos!$A:$A,0)),"") -> Sí | H10: =IFERROR(INDEX(Requerimientos!$J:$J,MATCH($A10,Requerimientos!$A:$A,0)),"") -> RF-SA-02
A11: RF-AH-04 | B11: =IFERROR(INDEX(Requerimientos!$E:$E,MATCH($A11,Requerimientos!$A:$A,0)),"") -> Registrar servicios con nombre descripción precio imágenes y si tienen costo | C11: =IFERROR(INDEX(Requerimientos!$C:$C,MATCH($A11,Requerimientos!$A:$A,0)),"") -> Administrador de hotel | D11: =IFERROR(INDEX(Requerimientos!$I:$I,MATCH($A11,Requerimientos!$A:$A,0)),"") -> RecyclerView | E11: =IFERROR(INDEX(Requerimientos!$G:$G,MATCH($A11,Requerimientos!$A:$A,0)),"") -> Alta | F11: =IFERROR(INDEX(Requerimientos!$K:$K,MATCH($A11,Requerimientos!$A:$A,0)),"") -> Pendiente | G11: =IFERROR(INDEX(Requerimientos!$L:$L,MATCH($A11,Requerimientos!$A:$A,0)),"") -> Sí | H11: =IFERROR(INDEX(Requerimientos!$J:$J,MATCH($A11,Requerimientos!$A:$A,0)),"") -> RF-SA-02
A12: RF-CL-02 | B12: =IFERROR(INDEX(Requerimientos!$E:$E,MATCH($A12,Requerimientos!$A:$A,0)),"") -> Consultar hoteles habitaciones servicios disponibilidad y valoraciones | C12: =IFERROR(INDEX(Requerimientos!$C:$C,MATCH($A12,Requerimientos!$A:$A,0)),"") -> Cliente | D12: =IFERROR(INDEX(Requerimientos!$I:$I,MATCH($A12,Requerimientos!$A:$A,0)),"") -> RecyclerView | E12: =IFERROR(INDEX(Requerimientos!$G:$G,MATCH($A12,Requerimientos!$A:$A,0)),"") -> Alta | F12: =IFERROR(INDEX(Requerimientos!$K:$K,MATCH($A12,Requerimientos!$A:$A,0)),"") -> Pendiente | G12: =IFERROR(INDEX(Requerimientos!$L:$L,MATCH($A12,Requerimientos!$A:$A,0)),"") -> Sí | H12: =IFERROR(INDEX(Requerimientos!$J:$J,MATCH($A12,Requerimientos!$A:$A,0)),"") -> RF-AH-01
A13: RF-CL-06 | B13: =IFERROR(INDEX(Requerimientos!$E:$E,MATCH($A13,Requerimientos!$A:$A,0)),"") -> Ver el historial de sus reservas | C13: =IFERROR(INDEX(Requerimientos!$C:$C,MATCH($A13,Requerimientos!$A:$A,0)),"") -> Cliente | D13: =IFERROR(INDEX(Requerimientos!$I:$I,MATCH($A13,Requerimientos!$A:$A,0)),"") -> RecyclerView | E13: =IFERROR(INDEX(Requerimientos!$G:$G,MATCH($A13,Requerimientos!$A:$A,0)),"") -> Media | F13: =IFERROR(INDEX(Requerimientos!$K:$K,MATCH($A13,Requerimientos!$A:$A,0)),"") -> Pendiente | G13: =IFERROR(INDEX(Requerimientos!$L:$L,MATCH($A13,Requerimientos!$A:$A,0)),"") -> Sí | H13: =IFERROR(INDEX(Requerimientos!$J:$J,MATCH($A13,Requerimientos!$A:$A,0)),"") -> RF-CL-03
A15: Lab 5 · 20/10/2026 · 3 requerimientos
A16: RF-AH-02 | B16: =IFERROR(INDEX(Requerimientos!$E:$E,MATCH($A16,Requerimientos!$A:$A,0)),"") -> Subir fotos del hotel con un mínimo de 4 | C16: =IFERROR(INDEX(Requerimientos!$C:$C,MATCH($A16,Requerimientos!$A:$A,0)),"") -> Administrador de hotel | D16: =IFERROR(INDEX(Requerimientos!$I:$I,MATCH($A16,Requerimientos!$A:$A,0)),"") -> Storage local | E16: =IFERROR(INDEX(Requerimientos!$G:$G,MATCH($A16,Requerimientos!$A:$A,0)),"") -> Alta | F16: =IFERROR(INDEX(Requerimientos!$K:$K,MATCH($A16,Requerimientos!$A:$A,0)),"") -> Pendiente | G16: =IFERROR(INDEX(Requerimientos!$L:$L,MATCH($A16,Requerimientos!$A:$A,0)),"") -> Sí | H16: =IFERROR(INDEX(Requerimientos!$J:$J,MATCH($A16,Requerimientos!$A:$A,0)),"") -> RF-SA-02
A17: RF-AH-06 | B17: =IFERROR(INDEX(Requerimientos!$E:$E,MATCH($A17,Requerimientos!$A:$A,0)),"") -> Recibir la alerta de checkout y procesar el cobro de la tarjeta registrada | C17: =IFERROR(INDEX(Requerimientos!$C:$C,MATCH($A17,Requerimientos!$A:$A,0)),"") -> Administrador de hotel | D17: =IFERROR(INDEX(Requerimientos!$I:$I,MATCH($A17,Requerimientos!$A:$A,0)),"") -> Notificaciones | E17: =IFERROR(INDEX(Requerimientos!$G:$G,MATCH($A17,Requerimientos!$A:$A,0)),"") -> Alta | F17: =IFERROR(INDEX(Requerimientos!$K:$K,MATCH($A17,Requerimientos!$A:$A,0)),"") -> Pendiente | G17: =IFERROR(INDEX(Requerimientos!$L:$L,MATCH($A17,Requerimientos!$A:$A,0)),"") -> Sí | H17: =IFERROR(INDEX(Requerimientos!$J:$J,MATCH($A17,Requerimientos!$A:$A,0)),"") -> RF-CL-04
A18: RF-CL-05 | B18: =IFERROR(INDEX(Requerimientos!$E:$E,MATCH($A18,Requerimientos!$A:$A,0)),"") -> Recibir notificación cuando se le hace el cobro | C18: =IFERROR(INDEX(Requerimientos!$C:$C,MATCH($A18,Requerimientos!$A:$A,0)),"") -> Cliente | D18: =IFERROR(INDEX(Requerimientos!$I:$I,MATCH($A18,Requerimientos!$A:$A,0)),"") -> Notificaciones | E18: =IFERROR(INDEX(Requerimientos!$G:$G,MATCH($A18,Requerimientos!$A:$A,0)),"") -> Alta | F18: =IFERROR(INDEX(Requerimientos!$K:$K,MATCH($A18,Requerimientos!$A:$A,0)),"") -> Pendiente | G18: =IFERROR(INDEX(Requerimientos!$L:$L,MATCH($A18,Requerimientos!$A:$A,0)),"") -> Parcial | H18: =IFERROR(INDEX(Requerimientos!$J:$J,MATCH($A18,Requerimientos!$A:$A,0)),"") -> RF-AH-06
A20: Lab 6 · 03/11/2026 · 19 requerimientos
A21: RF-SA-01 | B21: =IFERROR(INDEX(Requerimientos!$E:$E,MATCH($A21,Requerimientos!$A:$A,0)),"") -> Activar y desactivar administradores de hotel taxistas y clientes | C21: =IFERROR(INDEX(Requerimientos!$C:$C,MATCH($A21,Requerimientos!$A:$A,0)),"") -> Superadmin | D21: =IFERROR(INDEX(Requerimientos!$I:$I,MATCH($A21,Requerimientos!$A:$A,0)),"") -> Firebase Authentication | E21: =IFERROR(INDEX(Requerimientos!$G:$G,MATCH($A21,Requerimientos!$A:$A,0)),"") -> Alta | F21: =IFERROR(INDEX(Requerimientos!$K:$K,MATCH($A21,Requerimientos!$A:$A,0)),"") -> Pendiente | G21: =IFERROR(INDEX(Requerimientos!$L:$L,MATCH($A21,Requerimientos!$A:$A,0)),"") -> No | H21: =IFERROR(INDEX(Requerimientos!$J:$J,MATCH($A21,Requerimientos!$A:$A,0)),"") -> 0
A22: RF-SA-02 | B22: =IFERROR(INDEX(Requerimientos!$E:$E,MATCH($A22,Requerimientos!$A:$A,0)),"") -> Registrar hoteles y asignar un administrador a cada uno | C22: =IFERROR(INDEX(Requerimientos!$C:$C,MATCH($A22,Requerimientos!$A:$A,0)),"") -> Superadmin | D22: =IFERROR(INDEX(Requerimientos!$I:$I,MATCH($A22,Requerimientos!$A:$A,0)),"") -> Firebase Database | E22: =IFERROR(INDEX(Requerimientos!$G:$G,MATCH($A22,Requerimientos!$A:$A,0)),"") -> Alta | F22: =IFERROR(INDEX(Requerimientos!$K:$K,MATCH($A22,Requerimientos!$A:$A,0)),"") -> Pendiente | G22: =IFERROR(INDEX(Requerimientos!$L:$L,MATCH($A22,Requerimientos!$A:$A,0)),"") -> No | H22: =IFERROR(INDEX(Requerimientos!$J:$J,MATCH($A22,Requerimientos!$A:$A,0)),"") -> 0
A23: RF-AH-01 | B23: =IFERROR(INDEX(Requerimientos!$E:$E,MATCH($A23,Requerimientos!$A:$A,0)),"") -> Registrar la ubicación del hotel y los lugares históricos cercanos | C23: =IFERROR(INDEX(Requerimientos!$C:$C,MATCH($A23,Requerimientos!$A:$A,0)),"") -> Administrador de hotel | D23: =IFERROR(INDEX(Requerimientos!$I:$I,MATCH($A23,Requerimientos!$A:$A,0)),"") -> Firebase Database | E23: =IFERROR(INDEX(Requerimientos!$G:$G,MATCH($A23,Requerimientos!$A:$A,0)),"") -> Alta | F23: =IFERROR(INDEX(Requerimientos!$K:$K,MATCH($A23,Requerimientos!$A:$A,0)),"") -> Pendiente | G23: =IFERROR(INDEX(Requerimientos!$L:$L,MATCH($A23,Requerimientos!$A:$A,0)),"") -> No | H23: =IFERROR(INDEX(Requerimientos!$J:$J,MATCH($A23,Requerimientos!$A:$A,0)),"") -> RF-SA-02
A24: RF-AH-09 | B24: =IFERROR(INDEX(Requerimientos!$E:$E,MATCH($A24,Requerimientos!$A:$A,0)),"") -> Responder los chats de clientes con reserva activa | C24: =IFERROR(INDEX(Requerimientos!$C:$C,MATCH($A24,Requerimientos!$A:$A,0)),"") -> Administrador de hotel | D24: =IFERROR(INDEX(Requerimientos!$I:$I,MATCH($A24,Requerimientos!$A:$A,0)),"") -> Firebase Database | E24: =IFERROR(INDEX(Requerimientos!$G:$G,MATCH($A24,Requerimientos!$A:$A,0)),"") -> Alta | F24: =IFERROR(INDEX(Requerimientos!$K:$K,MATCH($A24,Requerimientos!$A:$A,0)),"") -> Pendiente | G24: =IFERROR(INDEX(Requerimientos!$L:$L,MATCH($A24,Requerimientos!$A:$A,0)),"") -> Sí | H24: =IFERROR(INDEX(Requerimientos!$J:$J,MATCH($A24,Requerimientos!$A:$A,0)),"") -> RF-CL-07
